[2019-10-01 13:22:34,478] : [ERROR] : [bleServerLogger] : [bleServer.py] : [advertiseBluetoothService] : Failed to advertise bluetooth services  ... 
Traceback (most recent call last):
  File "bleServer.py", line 77, in advertiseBluetoothService
    profiles = [ SERIAL_PORT_PROFILE ],
  File "/usr/lib/python2.7/dist-packages/bluetooth/bluez.py", line 176, in advertise_service
    raise BluetoothError (str (e))
BluetoothError: (2, 'No such file or directory')
[2019-10-01 13:26:04,319] : [ERROR] : [bleServerLogger] : [bleServer.py] : [acceptBluetoothConnection] : Failed to accept bluetooth connection ... 
Traceback (most recent call last):
  File "bleServer.py", line 86, in acceptBluetoothConnection
    self.clientSocket, clientInfo = self.serverSocket.accept()
  File "/usr/lib/python2.7/dist-packages/bluetooth/bluez.py", line 129, in accept
    client, addr = self._sock.accept ()
KeyboardInterrupt
[2019-10-01 13:26:04,322] : [ERROR] : [bleServerLogger] : [bleServer.py] : [deserializedData] : Failed to de-serialized string ... 
Traceback (most recent call last):
  File "bleServer.py", line 113, in deserializedData
    self.dataObj=pickle.loads(_dataRecv)
TypeError: loads() argument 1 must be string, not None
[2019-10-01 13:26:04,326] : [ERROR] : [bleServerLogger] : [bleServer.py] : [closeBluetoothSocket] : Failed to close the bluetooth sockets 
Traceback (most recent call last):
  File "bleServer.py", line 135, in closeBluetoothSocket
    self.clientSocket.close()
AttributeError: 'NoneType' object has no attribute 'close'
[2019-10-01 13:33:58,251] : [ERROR] : [bleClientLogger] : [bleClient.py] : [getBluetoothServices] : Couldn't find the RaspberryPi Bluetooth service : Invalid uuid
Traceback (most recent call last):
  File "bleClient.py", line 51, in getBluetoothServices
    bleService = find_service( uuid = self.uuid, address = self.addr )
  File "/usr/lib/python2.7/dist-packages/bluetooth/bluez.py", line 186, in find_service
    devices = discover_devices ()
  File "/usr/lib/python2.7/dist-packages/bluetooth/bluez.py", line 22, in discover_devices
    raise BluetoothError ("error communicating with local "
BluetoothError: error communicating with local bluetooth adapter
[2019-10-01 13:51:06,418] : [ERROR] : [bleClientLogger] : [bleClient.py] : [getBluetoothServices] : Couldn't find the RaspberryPi Bluetooth service : Invalid uuid
Traceback (most recent call last):
  File "bleClient.py", line 51, in getBluetoothServices
    bleService = find_service( uuid = self.uuid, address = self.addr )
  File "/usr/lib/python2.7/dist-packages/bluetooth/bluez.py", line 186, in find_service
    devices = discover_devices ()
  File "/usr/lib/python2.7/dist-packages/bluetooth/bluez.py", line 22, in discover_devices
    raise BluetoothError ("error communicating with local "
BluetoothError: error communicating with local bluetooth adapter
[2019-10-01 13:51:41,713] : [ERROR] : [bleServerLogger] : [bleServer.py] : [advertiseBluetoothService] : Failed to advertise bluetooth services  ... 
Traceback (most recent call last):
  File "bleServer.py", line 77, in advertiseBluetoothService
    profiles = [ SERIAL_PORT_PROFILE ],
  File "/usr/lib/python2.7/dist-packages/bluetooth/bluez.py", line 176, in advertise_service
    raise BluetoothError (str (e))
BluetoothError: (2, 'No such file or directory')
[2019-10-01 14:03:59,687] : [ERROR] : [bleServerLogger] : [bleServer.py] : [advertiseBluetoothService] : Failed to advertise bluetooth services  ... 
Traceback (most recent call last):
  File "bleServer.py", line 77, in advertiseBluetoothService
    profiles = [ SERIAL_PORT_PROFILE ],
  File "/usr/lib/python2.7/dist-packages/bluetooth/bluez.py", line 176, in advertise_service
    raise BluetoothError (str (e))
BluetoothError: (2, 'No such file or directory')
[2019-10-01 14:08:39,969] : [ERROR] : [bleServerLogger] : [bleServer.py] : [acceptBluetoothConnection] : Failed to accept bluetooth connection ... 
Traceback (most recent call last):
  File "bleServer.py", line 86, in acceptBluetoothConnection
    self.clientSocket, clientInfo = self.serverSocket.accept()
  File "/usr/lib/python2.7/dist-packages/bluetooth/bluez.py", line 129, in accept
    client, addr = self._sock.accept ()
KeyboardInterrupt
[2019-10-01 14:08:39,971] : [ERROR] : [bleServerLogger] : [bleServer.py] : [deserializedData] : Failed to de-serialized string ... 
Traceback (most recent call last):
  File "bleServer.py", line 113, in deserializedData
    self.dataObj=pickle.loads(_dataRecv)
TypeError: loads() argument 1 must be string, not None
[2019-10-01 14:08:39,976] : [ERROR] : [bleServerLogger] : [bleServer.py] : [closeBluetoothSocket] : Failed to close the bluetooth sockets 
Traceback (most recent call last):
  File "bleServer.py", line 135, in closeBluetoothSocket
    self.clientSocket.close()
AttributeError: 'NoneType' object has no attribute 'close'
[2019-10-01 14:08:40,898] : [ERROR] : [bleServerLogger] : [bleServer.py] : [advertiseBluetoothService] : Failed to advertise bluetooth services  ... 
Traceback (most recent call last):
  File "bleServer.py", line 77, in advertiseBluetoothService
    profiles = [ SERIAL_PORT_PROFILE ],
  File "/usr/lib/python2.7/dist-packages/bluetooth/bluez.py", line 176, in advertise_service
    raise BluetoothError (str (e))
BluetoothError: (2, 'No such file or directory')
[2019-10-01 14:09:53,037] : [ERROR] : [bleServerLogger] : [bleServer.py] : [acceptBluetoothConnection] : Failed to accept bluetooth connection ... 
Traceback (most recent call last):
  File "bleServer.py", line 86, in acceptBluetoothConnection
    self.clientSocket, clientInfo = self.serverSocket.accept()
  File "/usr/lib/python2.7/dist-packages/bluetooth/bluez.py", line 129, in accept
    client, addr = self._sock.accept ()
KeyboardInterrupt
[2019-10-01 14:09:53,039] : [ERROR] : [bleServerLogger] : [bleServer.py] : [deserializedData] : Failed to de-serialized string ... 
Traceback (most recent call last):
  File "bleServer.py", line 113, in deserializedData
    self.dataObj=pickle.loads(_dataRecv)
TypeError: loads() argument 1 must be string, not None
[2019-10-01 14:09:53,041] : [ERROR] : [bleServerLogger] : [bleServer.py] : [closeBluetoothSocket] : Failed to close the bluetooth sockets 
Traceback (most recent call last):
  File "bleServer.py", line 135, in closeBluetoothSocket
    self.clientSocket.close()
AttributeError: 'NoneType' object has no attribute 'close'
[2019-10-01 14:09:56,444] : [ERROR] : [bleServerLogger] : [bleServer.py] : [advertiseBluetoothService] : Failed to advertise bluetooth services  ... 
Traceback (most recent call last):
  File "bleServer.py", line 77, in advertiseBluetoothService
    profiles = [ SERIAL_PORT_PROFILE ],
  File "/usr/lib/python2.7/dist-packages/bluetooth/bluez.py", line 176, in advertise_service
    raise BluetoothError (str (e))
BluetoothError: (2, 'No such file or directory')
[2019-10-08 13:27:15,313] : [ERROR] : [bleClientLogger] : [bleClient.py] : [getBluetoothConnection] : Failed to connect to "BluetoothServices" on address B8:27:EB:B6:74:28 with port 1
Traceback (most recent call last):
  File "bleClient.py", line 83, in getBluetoothConnection
    self.clientSocket.connect((bleServiceInfo['host'], bleServiceInfo['port']))
  File "<string>", line 5, in connect
BluetoothError: (16, 'Device or resource busy')
[2019-10-08 13:27:15,316] : [ERROR] : [bleClientLogger] : [bleClient.py] : [readJsonFile] : Failed to load content from the text.json
Traceback (most recent call last):
  File "bleClient.py", line 90, in readJsonFile
    jsonFileObj = open(self.lsonFile,"r")
AttributeError: bleClient instance has no attribute 'lsonFile'
[2019-10-08 13:27:15,319] : [ERROR] : [bleClientLogger] : [bleClient.py] : [sendData] : Failed to send data over bluetooth connection
Traceback (most recent call last):
  File "bleClient.py", line 110, in sendData
    self.clientSocket.send(_serializedData)
  File "<string>", line 5, in send
BluetoothError: (107, 'Transport endpoint is not connected')
[2019-10-08 13:27:53,156] : [ERROR] : [bleClientLogger] : [bleClient.py] : [getBluetoothServices] : Couldn't find the RaspberryPi Bluetooth service : Invalid uuid
Traceback (most recent call last):
  File "bleClient.py", line 51, in getBluetoothServices
    bleService = find_service( uuid = self.uuid, address = self.addr )
  File "/usr/lib/python2.7/dist-packages/bluetooth/bluez.py", line 199, in find_service
    s.connect (addr)
KeyboardInterrupt
[2019-10-08 13:32:41,490] : [ERROR] : [bleClientLogger] : [bleClient.py] : [getBluetoothConnection] : Failed to connect to "BluetoothServices" on address B8:27:EB:B6:74:28 with port 1
Traceback (most recent call last):
  File "bleClient.py", line 83, in getBluetoothConnection
    self.clientSocket.connect((bleServiceInfo['host'], bleServiceInfo['port']))
  File "<string>", line 5, in connect
BluetoothError: (16, 'Device or resource busy')
[2019-10-08 13:32:41,492] : [ERROR] : [bleClientLogger] : [bleClient.py] : [sendData] : Failed to send data over bluetooth connection
Traceback (most recent call last):
  File "bleClient.py", line 110, in sendData
    self.clientSocket.send(_serializedData)
  File "<string>", line 5, in send
BluetoothError: (107, 'Transport endpoint is not connected')
[2019-10-08 13:33:02,622] : [ERROR] : [bleClientLogger] : [bleClient.py] : [getBluetoothServices] : Couldn't find the RaspberryPi Bluetooth service : Invalid uuid
Traceback (most recent call last):
  File "bleClient.py", line 51, in getBluetoothServices
    bleService = find_service( uuid = self.uuid, address = self.addr )
  File "/usr/lib/python2.7/dist-packages/bluetooth/bluez.py", line 199, in find_service
    s.connect (addr)
KeyboardInterrupt
[2019-10-08 13:38:29,383] : [ERROR] : [bleClientLogger] : [bleClient.py] : [getBluetoothServices] : Couldn't find the RaspberryPi Bluetooth service : Invalid uuid
Traceback (most recent call last):
  File "bleClient.py", line 56, in getBluetoothServices
    if not bleService: raise SystemExit(), KeyboardInterrupt()
TypeError: instance exception may not have a separate value
[2019-10-08 13:48:04,927] : [ERROR] : [bleClientLogger] : [bleClient.py] : [getBluetoothServices] : Couldn't find the RaspberryPi Bluetooth service : Invalid uuid
Traceback (most recent call last):
  File "bleClient.py", line 51, in getBluetoothServices
    bleService = find_service( uuid = self.uuid, address = self.addr )
  File "/usr/lib/python2.7/dist-packages/bluetooth/bluez.py", line 199, in find_service
    s.connect (addr)
KeyboardInterrupt
[2019-10-08 14:09:06,945] : [ERROR] : [bleClientLogger] : [bleClient.py] : [getBluetoothConnection] : Failed to connect to "BluetoothServices" on address B8:27:EB:B6:74:28 with port 1
Traceback (most recent call last):
  File "bleClient.py", line 83, in getBluetoothConnection
    self.clientSocket.connect((bleServiceInfo['host'], bleServiceInfo['port']))
  File "<string>", line 5, in connect
BluetoothError: (111, 'Connection refused')
[2019-10-08 14:09:06,946] : [ERROR] : [bleClientLogger] : [bleClient.py] : [sendData] : Failed to send data over bluetooth connection
Traceback (most recent call last):
  File "bleClient.py", line 110, in sendData
    self.clientSocket.send(_serializedData)
  File "<string>", line 5, in send
BluetoothError: (107, 'Transport endpoint is not connected')
[2019-10-08 14:11:54,555] : [ERROR] : [bleClientLogger] : [bleClient.py] : [getBluetoothServices] : Couldn't find the RaspberryPi Bluetooth service : Invalid uuid
Traceback (most recent call last):
  File "bleClient.py", line 51, in getBluetoothServices
    bleService = find_service( uuid = self.uuid, address = self.addr )
  File "/usr/lib/python2.7/dist-packages/bluetooth/bluez.py", line 199, in find_service
    s.connect (addr)
KeyboardInterrupt
[2019-10-08 14:13:37,678] : [ERROR] : [bleClientLogger] : [bleClient.py] : [getBluetoothConnection] : Failed to connect to "BluetoothServices" on address B8:27:EB:B6:74:28 with port 1
Traceback (most recent call last):
  File "bleClient.py", line 83, in getBluetoothConnection
    self.clientSocket.connect((bleServiceInfo['host'], bleServiceInfo['port']))
  File "<string>", line 5, in connect
BluetoothError: (111, 'Connection refused')
[2019-10-08 14:13:37,684] : [ERROR] : [bleClientLogger] : [bleClient.py] : [sendData] : Failed to send data over bluetooth connection
Traceback (most recent call last):
  File "bleClient.py", line 110, in sendData
    self.clientSocket.send(_serializedData)
  File "<string>", line 5, in send
BluetoothError: (107, 'Transport endpoint is not connected')
[2019-10-08 14:29:06,526] : [ERROR] : [bleClientLogger] : [bleClient.py] : [getBluetoothServices] : Couldn't find the RaspberryPi Bluetooth service : Invalid uuid
Traceback (most recent call last):
  File "bleClient.py", line 51, in getBluetoothServices
    bleService = find_service( uuid = self.uuid, address = self.addr )
  File "/usr/lib/python2.7/dist-packages/bluetooth/bluez.py", line 199, in find_service
    s.connect (addr)
KeyboardInterrupt
[2019-10-08 14:32:48,627] : [ERROR] : [bleClientLogger] : [bleClient.py] : [getBluetoothServices] : Couldn't find the RaspberryPi Bluetooth service : Invalid uuid
Traceback (most recent call last):
  File "bleClient.py", line 56, in getBluetoothServices
    if not bleService: raise SystemExit(), KeyboardInterrupt()
TypeError: instance exception may not have a separate value
[2019-10-08 14:37:16,646] : [ERROR] : [bleClientLogger] : [bleClient.py] : [getBluetoothServices] : Couldn't find the RaspberryPi Bluetooth service : Invalid uuid
Traceback (most recent call last):
  File "bleClient.py", line 56, in getBluetoothServices
    if not bleService: raise SystemExit(), KeyboardInterrupt()
TypeError: instance exception may not have a separate value
[2019-10-08 14:41:40,806] : [ERROR] : [bleClientLogger] : [bleClient.py] : [getBluetoothServices] : Couldn't find the RaspberryPi Bluetooth service : Invalid uuid
Traceback (most recent call last):
  File "bleClient.py", line 56, in getBluetoothServices
    if not bleService: raise SystemExit(), KeyboardInterrupt()
TypeError: instance exception may not have a separate value
[2019-10-08 14:45:00,721] : [ERROR] : [bleClientLogger] : [bleClient.py] : [getBluetoothServices] : Couldn't find the RaspberryPi Bluetooth service : Invalid uuid
Traceback (most recent call last):
  File "bleClient.py", line 51, in getBluetoothServices
    bleService = find_service( uuid = self.uuid, address = self.addr )
  File "/usr/lib/python2.7/dist-packages/bluetooth/bluez.py", line 199, in find_service
    s.connect (addr)
KeyboardInterrupt
[2019-10-08 14:49:57,066] : [ERROR] : [bleClientLogger] : [bleClient.py] : [getBluetoothServices] : Couldn't find the RaspberryPi Bluetooth service : Invalid uuid
Traceback (most recent call last):
  File "bleClient.py", line 56, in getBluetoothServices
    if not bleService: raise SystemExit(), KeyboardInterrupt()
TypeError: instance exception may not have a separate value
[2019-10-08 15:00:38,558] : [ERROR] : [bleClientLogger] : [bleClient.py] : [getBluetoothServices] : Couldn't find the RaspberryPi Bluetooth service : Invalid uuid
Traceback (most recent call last):
  File "bleClient.py", line 51, in getBluetoothServices
    bleService = find_service( uuid = self.uuid, address = self.addr )
  File "/usr/lib/python2.7/dist-packages/bluetooth/bluez.py", line 186, in find_service
    devices = discover_devices ()
  File "/usr/lib/python2.7/dist-packages/bluetooth/bluez.py", line 22, in discover_devices
    raise BluetoothError ("error communicating with local "
BluetoothError: error communicating with local bluetooth adapter
[2019-10-08 15:00:44,496] : [ERROR] : [bleClientLogger] : [bleClient.py] : [getBluetoothServices] : Couldn't find the RaspberryPi Bluetooth service : Invalid uuid
Traceback (most recent call last):
  File "bleClient.py", line 51, in getBluetoothServices
    bleService = find_service( uuid = self.uuid, address = self.addr )
  File "/usr/lib/python2.7/dist-packages/bluetooth/bluez.py", line 186, in find_service
    devices = discover_devices ()
  File "/usr/lib/python2.7/dist-packages/bluetooth/bluez.py", line 22, in discover_devices
    raise BluetoothError ("error communicating with local "
BluetoothError: error communicating with local bluetooth adapter
[2019-10-08 15:01:13,374] : [ERROR] : [bleClientLogger] : [bleClient.py] : [getBluetoothServices] : Couldn't find the RaspberryPi Bluetooth service : Invalid uuid
Traceback (most recent call last):
  File "bleClient.py", line 51, in getBluetoothServices
    bleService = find_service( uuid = self.uuid, address = self.addr )
  File "/usr/lib/python2.7/dist-packages/bluetooth/bluez.py", line 186, in find_service
    devices = discover_devices ()
  File "/usr/lib/python2.7/dist-packages/bluetooth/bluez.py", line 22, in discover_devices
    raise BluetoothError ("error communicating with local "
BluetoothError: error communicating with local bluetooth adapter
[2019-10-08 15:03:18,751] : [ERROR] : [bleClientLogger] : [bleClient.py] : [getBluetoothServices] : Couldn't find the RaspberryPi Bluetooth service : Invalid uuid
Traceback (most recent call last):
  File "bleClient.py", line 56, in getBluetoothServices
    if not bleService: raise SystemExit(), KeyboardInterrupt()
TypeError: instance exception may not have a separate value
[2019-10-08 15:04:23,220] : [ERROR] : [bleClientLogger] : [bleClient.py] : [getBluetoothServices] : Couldn't find the RaspberryPi Bluetooth service : Invalid uuid
Traceback (most recent call last):
  File "bleClient.py", line 51, in getBluetoothServices
    bleService = find_service( uuid = self.uuid, address = self.addr )
  File "/usr/lib/python2.7/dist-packages/bluetooth/bluez.py", line 199, in find_service
    s.connect (addr)
KeyboardInterrupt
[2019-10-08 15:12:22,610] : [ERROR] : [bleClientLogger] : [bleClient.py] : [getBluetoothServices] : Couldn't find the RaspberryPi Bluetooth service : Invalid uuid
Traceback (most recent call last):
  File "bleClient.py", line 56, in getBluetoothServices
    if not bleService: raise SystemExit(), KeyboardInterrupt()
TypeError: instance exception may not have a separate value
[2019-10-08 15:23:19,109] : [ERROR] : [bleClientLogger] : [bleClient.py] : [getBluetoothServices] : Couldn't find the RaspberryPi Bluetooth service : Invalid uuid
Traceback (most recent call last):
  File "bleClient.py", line 51, in getBluetoothServices
    bleService = find_service( uuid = self.uuid, address = self.addr )
  File "/usr/lib/python2.7/dist-packages/bluetooth/bluez.py", line 186, in find_service
    devices = discover_devices ()
  File "/usr/lib/python2.7/dist-packages/bluetooth/bluez.py", line 22, in discover_devices
    raise BluetoothError ("error communicating with local "
BluetoothError: error communicating with local bluetooth adapter
[2019-10-09 11:59:25,314] : [ERROR] : [bleClientLogger] : [bleClient.py] : [getBluetoothServices] : Couldn't find the RaspberryPi Bluetooth service : Invalid uuid
Traceback (most recent call last):
  File "bleClient.py", line 56, in getBluetoothServices
    if not bleService: raise SystemExit(), KeyboardInterrupt()
TypeError: instance exception may not have a separate value
[2019-10-09 12:34:39,405] : [ERROR] : [bleClientLogger] : [bleClient.py] : [getBluetoothServices] : Couldn't find the RaspberryPi Bluetooth service : Invalid uuid
Traceback (most recent call last):
  File "bleClient.py", line 56, in getBluetoothServices
    if not bleService: raise SystemExit(), KeyboardInterrupt()
TypeError: instance exception may not have a separate value
[2019-10-09 12:42:17,428] : [ERROR] : [bleClientLogger] : [bleClient.py] : [getBluetoothServices] : Couldn't find the RaspberryPi Bluetooth service : Invalid uuid
Traceback (most recent call last):
  File "bleClient.py", line 56, in getBluetoothServices
    if not bleService: raise SystemExit(), KeyboardInterrupt()
TypeError: instance exception may not have a separate value
[2019-10-09 12:43:05,336] : [ERROR] : [bleClientLogger] : [bleClient.py] : [getBluetoothServices] : Couldn't find the RaspberryPi Bluetooth service : Invalid uuid
Traceback (most recent call last):
  File "bleClient.py", line 51, in getBluetoothServices
    bleService = find_service( uuid = self.uuid, address = self.addr )
  File "/usr/lib/python2.7/dist-packages/bluetooth/bluez.py", line 186, in find_service
    devices = discover_devices ()
  File "/usr/lib/python2.7/dist-packages/bluetooth/bluez.py", line 19, in discover_devices
    results = _bt.hci_inquiry (sock, duration=duration, flush_cache=True)
KeyboardInterrupt
[2019-10-09 12:44:02,051] : [ERROR] : [bleClientLogger] : [bleClient.py] : [getBluetoothServices] : Couldn't find the RaspberryPi Bluetooth service : Invalid uuid
Traceback (most recent call last):
  File "bleClient.py", line 56, in getBluetoothServices
    if not bleService: raise SystemExit(), KeyboardInterrupt()
TypeError: instance exception may not have a separate value
[2019-10-09 12:54:05,555] : [ERROR] : [bleClientLogger] : [bleClient.py] : [getBluetoothServices] : Couldn't find the RaspberryPi Bluetooth service : Invalid uuid
Traceback (most recent call last):
  File "bleClient.py", line 56, in getBluetoothServices
    if not bleService: raise SystemExit(), KeyboardInterrupt()
TypeError: instance exception may not have a separate value
[2019-10-09 12:54:50,248] : [ERROR] : [bleClientLogger] : [bleClient.py] : [getBluetoothServices] : Couldn't find the RaspberryPi Bluetooth service : Invalid uuid
Traceback (most recent call last):
  File "bleClient.py", line 56, in getBluetoothServices
    if not bleService: raise SystemExit(), KeyboardInterrupt()
TypeError: instance exception may not have a separate value
[2019-10-09 12:58:47,049] : [ERROR] : [bleClientLogger] : [bleClient.py] : [getBluetoothServices] : Couldn't find the RaspberryPi Bluetooth service : Invalid uuid
Traceback (most recent call last):
  File "bleClient.py", line 56, in getBluetoothServices
    if not bleService: raise SystemExit(), KeyboardInterrupt()
TypeError: instance exception may not have a separate value
[2019-10-09 13:17:10,860] : [ERROR] : [bleClientLogger] : [bleClient.py] : [getBluetoothServices] : Couldn't find the RaspberryPi Bluetooth service : Invalid uuid
Traceback (most recent call last):
  File "bleClient.py", line 56, in getBluetoothServices
    if not bleService: raise SystemExit(), KeyboardInterrupt()
TypeError: instance exception may not have a separate value
[2019-10-09 13:17:46,923] : [ERROR] : [bleClientLogger] : [bleClient.py] : [getBluetoothServices] : Couldn't find the RaspberryPi Bluetooth service : Invalid uuid
Traceback (most recent call last):
  File "bleClient.py", line 51, in getBluetoothServices
    bleService = find_service( uuid = self.uuid, address = self.addr )
  File "/usr/lib/python2.7/dist-packages/bluetooth/bluez.py", line 199, in find_service
    s.connect (addr)
KeyboardInterrupt
[2019-10-09 13:21:39,265] : [ERROR] : [bleClientLogger] : [bleClient.py] : [getBluetoothServices] : Couldn't find the RaspberryPi Bluetooth service : Invalid uuid
Traceback (most recent call last):
  File "bleClient.py", line 56, in getBluetoothServices
    if not bleService: raise SystemExit(), KeyboardInterrupt()
TypeError: instance exception may not have a separate value
[2019-10-09 13:26:08,790] : [ERROR] : [bleClientLogger] : [bleClient.py] : [getBluetoothServices] : Couldn't find the RaspberryPi Bluetooth service : Invalid uuid
Traceback (most recent call last):
  File "bleClient.py", line 51, in getBluetoothServices
    bleService = find_service( uuid = self.uuid, address = self.addr )
  File "/usr/lib/python2.7/dist-packages/bluetooth/bluez.py", line 199, in find_service
    s.connect (addr)
KeyboardInterrupt
[2019-10-09 15:08:03,922] : [ERROR] : [bleClientLogger] : [bleClient.py] : [getBluetoothServices] : Couldn't find the RaspberryPi Bluetooth service : Invalid uuid
Traceback (most recent call last):
  File "bleClient.py", line 56, in getBluetoothServices
    if not bleService: raise SystemExit(), KeyboardInterrupt()
TypeError: instance exception may not have a separate value
[2019-10-15 11:46:58,620] : [ERROR] : [bleClientLogger] : [bleClient.py] : [getBluetoothServices] : Couldn't find the RaspberryPi Bluetooth service : Invalid uuid
Traceback (most recent call last):
  File "bleClient.py", line 51, in getBluetoothServices
    bleService = find_service( uuid = self.uuid, address = self.addr )
  File "/usr/lib/python2.7/dist-packages/bluetooth/bluez.py", line 186, in find_service
    devices = discover_devices ()
  File "/usr/lib/python2.7/dist-packages/bluetooth/bluez.py", line 19, in discover_devices
    results = _bt.hci_inquiry (sock, duration=duration, flush_cache=True)
KeyboardInterrupt
[2019-10-15 12:25:30,344] : [ERROR] : [bleClientLogger] : [bleClient.py] : [getBluetoothServices] : Couldn't find the RaspberryPi Bluetooth service : Invalid uuid
Traceback (most recent call last):
  File "bleClient.py", line 51, in getBluetoothServices
    bleService = find_service( uuid = self.uuid, address = self.addr )
  File "/usr/lib/python2.7/dist-packages/bluetooth/bluez.py", line 186, in find_service
    devices = discover_devices ()
  File "/usr/lib/python2.7/dist-packages/bluetooth/bluez.py", line 19, in discover_devices
    results = _bt.hci_inquiry (sock, duration=duration, flush_cache=True)
KeyboardInterrupt
[2019-10-15 12:33:59,639] : [ERROR] : [bleClientLogger] : [bleClient.py] : [getBluetoothServices] : Couldn't find the RaspberryPi Bluetooth service : Invalid uuid
Traceback (most recent call last):
  File "bleClient.py", line 51, in getBluetoothServices
    bleService = find_service( uuid = self.uuid, address = self.addr )
  File "/usr/lib/python2.7/dist-packages/bluetooth/bluez.py", line 186, in find_service
    devices = discover_devices ()
  File "/usr/lib/python2.7/dist-packages/bluetooth/bluez.py", line 19, in discover_devices
    results = _bt.hci_inquiry (sock, duration=duration, flush_cache=True)
KeyboardInterrupt
[2019-10-15 13:03:08,072] : [ERROR] : [bleServerLogger] : [bleServer.py] : [advertiseBluetoothService] : Failed to advertise bluetooth services  ... 
Traceback (most recent call last):
  File "bleServer.py", line 77, in advertiseBluetoothService
    profiles = [ SERIAL_PORT_PROFILE ],
  File "/usr/lib/python2.7/dist-packages/bluetooth/bluez.py", line 176, in advertise_service
    raise BluetoothError (str (e))
BluetoothError: (2, 'No such file or directory')
[2019-10-15 13:03:14,991] : [ERROR] : [bleServerLogger] : [bleServer.py] : [acceptBluetoothConnection] : Failed to accept bluetooth connection ... 
Traceback (most recent call last):
  File "bleServer.py", line 86, in acceptBluetoothConnection
    self.clientSocket, clientInfo = self.serverSocket.accept()
  File "/usr/lib/python2.7/dist-packages/bluetooth/bluez.py", line 129, in accept
    client, addr = self._sock.accept ()
KeyboardInterrupt
[2019-10-15 13:03:14,993] : [ERROR] : [bleServerLogger] : [bleServer.py] : [deserializedData] : Failed to de-serialized string ... 
Traceback (most recent call last):
  File "bleServer.py", line 113, in deserializedData
    self.dataObj=pickle.loads(_dataRecv)
TypeError: loads() argument 1 must be string, not None
[2019-10-15 13:03:14,997] : [ERROR] : [bleServerLogger] : [bleServer.py] : [closeBluetoothSocket] : Failed to close the bluetooth sockets 
Traceback (most recent call last):
  File "bleServer.py", line 135, in closeBluetoothSocket
    self.clientSocket.close()
AttributeError: 'NoneType' object has no attribute 'close'
[2019-10-15 13:03:24,146] : [ERROR] : [bleClientLogger] : [bleClient.py] : [getBluetoothServices] : Couldn't find the RaspberryPi Bluetooth service : Invalid uuid
Traceback (most recent call last):
  File "bleClient.py", line 51, in getBluetoothServices
    bleService = find_service( uuid = self.uuid, address = self.addr )
  File "/usr/lib/python2.7/dist-packages/bluetooth/bluez.py", line 186, in find_service
    devices = discover_devices ()
  File "/usr/lib/python2.7/dist-packages/bluetooth/bluez.py", line 19, in discover_devices
    results = _bt.hci_inquiry (sock, duration=duration, flush_cache=True)
KeyboardInterrupt
[2019-10-15 13:03:47,872] : [ERROR] : [bleClientLogger] : [bleClient.py] : [getBluetoothServices] : Couldn't find the RaspberryPi Bluetooth service : Invalid uuid
Traceback (most recent call last):
  File "bleClient.py", line 51, in getBluetoothServices
    bleService = find_service( uuid = self.uuid, address = self.addr )
  File "/usr/lib/python2.7/dist-packages/bluetooth/bluez.py", line 186, in find_service
    devices = discover_devices ()
  File "/usr/lib/python2.7/dist-packages/bluetooth/bluez.py", line 19, in discover_devices
    results = _bt.hci_inquiry (sock, duration=duration, flush_cache=True)
KeyboardInterrupt
[2019-10-15 13:03:59,257] : [ERROR] : [bleClientLogger] : [bleClient.py] : [getBluetoothServices] : Couldn't find the RaspberryPi Bluetooth service : Invalid uuid
Traceback (most recent call last):
  File "bleClient.py", line 51, in getBluetoothServices
    bleService = find_service( uuid = self.uuid, address = self.addr )
  File "/usr/lib/python2.7/dist-packages/bluetooth/bluez.py", line 186, in find_service
    devices = discover_devices ()
  File "/usr/lib/python2.7/dist-packages/bluetooth/bluez.py", line 19, in discover_devices
    results = _bt.hci_inquiry (sock, duration=duration, flush_cache=True)
KeyboardInterrupt
[2019-10-15 14:57:00,052] : [ERROR] : [bleServerLogger] : [bleReceiver.py] : [advertiseBluetoothService] : Failed to advertise bluetooth services  ... 
Traceback (most recent call last):
  File "bleReceiver.py", line 77, in advertiseBluetoothService
    profiles = [ SERIAL_PORT_PROFILE ],
  File "/usr/lib/python2.7/dist-packages/bluetooth/bluez.py", line 176, in advertise_service
    raise BluetoothError (str (e))
BluetoothError: (2, 'No such file or directory')
[2019-10-15 14:57:26,593] : [ERROR] : [bleServerLogger] : [bleReceiver.py] : [acceptBluetoothConnection] : Failed to accept bluetooth connection ... 
Traceback (most recent call last):
  File "bleReceiver.py", line 86, in acceptBluetoothConnection
    self.clientSocket, clientInfo = self.serverSocket.accept()
  File "/usr/lib/python2.7/dist-packages/bluetooth/bluez.py", line 129, in accept
    client, addr = self._sock.accept ()
KeyboardInterrupt
[2019-10-15 14:57:26,595] : [ERROR] : [bleServerLogger] : [bleReceiver.py] : [deserializedData] : Failed to de-serialized string ... 
Traceback (most recent call last):
  File "bleReceiver.py", line 113, in deserializedData
    self.dataObj=pickle.loads(_dataRecv)
TypeError: loads() argument 1 must be string, not None
[2019-10-15 14:57:26,598] : [ERROR] : [bleServerLogger] : [bleReceiver.py] : [closeBluetoothSocket] : Failed to close the bluetooth sockets 
Traceback (most recent call last):
  File "bleReceiver.py", line 135, in closeBluetoothSocket
    self.clientSocket.close()
AttributeError: 'NoneType' object has no attribute 'close'
[2019-10-15 15:04:30,214] : [ERROR] : [bleServerLogger] : [bleReceiver.py] : [advertiseBluetoothService] : Failed to advertise bluetooth services  ... 
Traceback (most recent call last):
  File "bleReceiver.py", line 77, in advertiseBluetoothService
    profiles = [ SERIAL_PORT_PROFILE ],
  File "/usr/lib/python2.7/dist-packages/bluetooth/bluez.py", line 176, in advertise_service
    raise BluetoothError (str (e))
BluetoothError: (2, 'No such file or directory')
[2019-10-15 15:07:39,784] : [ERROR] : [bleServerLogger] : [bleReceiver.py] : [acceptBluetoothConnection] : Failed to accept bluetooth connection ... 
Traceback (most recent call last):
  File "bleReceiver.py", line 86, in acceptBluetoothConnection
    self.clientSocket, clientInfo = self.serverSocket.accept()
  File "/usr/lib/python2.7/dist-packages/bluetooth/bluez.py", line 129, in accept
    client, addr = self._sock.accept ()
KeyboardInterrupt
[2019-10-15 15:07:39,787] : [ERROR] : [bleServerLogger] : [bleReceiver.py] : [deserializedData] : Failed to de-serialized string ... 
Traceback (most recent call last):
  File "bleReceiver.py", line 113, in deserializedData
    self.dataObj=pickle.loads(_dataRecv)
TypeError: loads() argument 1 must be string, not None
[2019-10-15 15:07:39,791] : [ERROR] : [bleServerLogger] : [bleReceiver.py] : [closeBluetoothSocket] : Failed to close the bluetooth sockets 
Traceback (most recent call last):
  File "bleReceiver.py", line 135, in closeBluetoothSocket
    self.clientSocket.close()
AttributeError: 'NoneType' object has no attribute 'close'
[2019-10-15 15:08:00,992] : [ERROR] : [bleServerLogger] : [bleReceiver.py] : [advertiseBluetoothService] : Failed to advertise bluetooth services  ... 
Traceback (most recent call last):
  File "bleReceiver.py", line 77, in advertiseBluetoothService
    profiles = [ SERIAL_PORT_PROFILE ],
  File "/usr/lib/python2.7/dist-packages/bluetooth/bluez.py", line 176, in advertise_service
    raise BluetoothError (str (e))
BluetoothError: (2, 'No such file or directory')
[2019-10-15 15:21:41,343] : [ERROR] : [bleServerLogger] : [bleReceiver.py] : [acceptBluetoothConnection] : Failed to accept bluetooth connection ... 
Traceback (most recent call last):
  File "bleReceiver.py", line 86, in acceptBluetoothConnection
    self.clientSocket, clientInfo = self.serverSocket.accept()
  File "/usr/lib/python2.7/dist-packages/bluetooth/bluez.py", line 129, in accept
    client, addr = self._sock.accept ()
KeyboardInterrupt
[2019-10-15 15:21:41,346] : [ERROR] : [bleServerLogger] : [bleReceiver.py] : [deserializedData] : Failed to de-serialized string ... 
Traceback (most recent call last):
  File "bleReceiver.py", line 113, in deserializedData
    self.dataObj=pickle.loads(_dataRecv)
TypeError: loads() argument 1 must be string, not None
[2019-10-15 15:21:41,351] : [ERROR] : [bleServerLogger] : [bleReceiver.py] : [closeBluetoothSocket] : Failed to close the bluetooth sockets 
Traceback (most recent call last):
  File "bleReceiver.py", line 135, in closeBluetoothSocket
    self.clientSocket.close()
AttributeError: 'NoneType' object has no attribute 'close'
[2019-10-15 15:29:16,623] : [ERROR] : [bleServerLogger] : [bleReceiver.py] : [advertiseBluetoothService] : Failed to advertise bluetooth services  ... 
Traceback (most recent call last):
  File "bleReceiver.py", line 77, in advertiseBluetoothService
    profiles = [ SERIAL_PORT_PROFILE ],
  File "/usr/lib/python2.7/dist-packages/bluetooth/bluez.py", line 176, in advertise_service
    raise BluetoothError (str (e))
BluetoothError: (2, 'No such file or directory')
[2019-10-15 18:59:48,163] : [ERROR] : [bleServerLogger] : [bleReceiver.py] : [acceptBluetoothConnection] : Failed to accept bluetooth connection ... 
Traceback (most recent call last):
  File "bleReceiver.py", line 86, in acceptBluetoothConnection
    self.clientSocket, clientInfo = self.serverSocket.accept()
  File "/usr/lib/python2.7/dist-packages/bluetooth/bluez.py", line 129, in accept
    client, addr = self._sock.accept ()
KeyboardInterrupt
[2019-10-15 18:59:48,163] : [ERROR] : [bleServerLogger] : [bleReceiver.py] : [deserializedData] : Failed to de-serialized string ... 
Traceback (most recent call last):
  File "bleReceiver.py", line 113, in deserializedData
    self.dataObj=pickle.loads(_dataRecv)
TypeError: loads() argument 1 must be string, not None
[2019-10-15 18:59:48,164] : [ERROR] : [bleServerLogger] : [bleReceiver.py] : [closeBluetoothSocket] : Failed to close the bluetooth sockets 
Traceback (most recent call last):
  File "bleReceiver.py", line 135, in closeBluetoothSocket
    self.clientSocket.close()
AttributeError: 'NoneType' object has no attribute 'close'
[2019-10-16 13:06:03,065] : [ERROR] : [bleServerLogger] : [bleReceiver.py] : [advertiseBluetoothService] : Failed to advertise bluetooth services  ... 
Traceback (most recent call last):
  File "bleReceiver.py", line 77, in advertiseBluetoothService
    profiles = [ SERIAL_PORT_PROFILE ],
  File "/usr/lib/python2.7/dist-packages/bluetooth/bluez.py", line 176, in advertise_service
    raise BluetoothError (str (e))
BluetoothError: (2, 'No such file or directory')
[2019-10-16 13:10:59,330] : [ERROR] : [bleServerLogger] : [bleReceiver.py] : [acceptBluetoothConnection] : Failed to accept bluetooth connection ... 
Traceback (most recent call last):
  File "bleReceiver.py", line 86, in acceptBluetoothConnection
    self.clientSocket, clientInfo = self.serverSocket.accept()
  File "/usr/lib/python2.7/dist-packages/bluetooth/bluez.py", line 129, in accept
    client, addr = self._sock.accept ()
KeyboardInterrupt
[2019-10-16 13:10:59,332] : [ERROR] : [bleServerLogger] : [bleReceiver.py] : [deserializedData] : Failed to de-serialized string ... 
Traceback (most recent call last):
  File "bleReceiver.py", line 113, in deserializedData
    self.dataObj=pickle.loads(_dataRecv)
TypeError: loads() argument 1 must be string, not None
[2019-10-16 13:10:59,338] : [ERROR] : [bleServerLogger] : [bleReceiver.py] : [closeBluetoothSocket] : Failed to close the bluetooth sockets 
Traceback (most recent call last):
  File "bleReceiver.py", line 135, in closeBluetoothSocket
    self.clientSocket.close()
AttributeError: 'NoneType' object has no attribute 'close'
[2019-10-16 13:14:35,678] : [ERROR] : [bleServerLogger] : [bleReceiver.py] : [advertiseBluetoothService] : Failed to advertise bluetooth services  ... 
Traceback (most recent call last):
  File "bleReceiver.py", line 77, in advertiseBluetoothService
    profiles = [ SERIAL_PORT_PROFILE ],
  File "/usr/lib/python2.7/dist-packages/bluetooth/bluez.py", line 176, in advertise_service
    raise BluetoothError (str (e))
BluetoothError: (2, 'No such file or directory')
[2019-10-16 13:17:51,374] : [ERROR] : [bleServerLogger] : [bleReceiver.py] : [acceptBluetoothConnection] : Failed to accept bluetooth connection ... 
Traceback (most recent call last):
  File "bleReceiver.py", line 86, in acceptBluetoothConnection
    self.clientSocket, clientInfo = self.serverSocket.accept()
  File "/usr/lib/python2.7/dist-packages/bluetooth/bluez.py", line 129, in accept
    client, addr = self._sock.accept ()
KeyboardInterrupt
[2019-10-16 13:17:51,377] : [ERROR] : [bleServerLogger] : [bleReceiver.py] : [deserializedData] : Failed to de-serialized string ... 
Traceback (most recent call last):
  File "bleReceiver.py", line 113, in deserializedData
    self.dataObj=pickle.loads(_dataRecv)
TypeError: loads() argument 1 must be string, not None
[2019-10-16 13:17:51,386] : [ERROR] : [bleServerLogger] : [bleReceiver.py] : [closeBluetoothSocket] : Failed to close the bluetooth sockets 
Traceback (most recent call last):
  File "bleReceiver.py", line 135, in closeBluetoothSocket
    self.clientSocket.close()
AttributeError: 'NoneType' object has no attribute 'close'
[2019-10-16 13:33:10,253] : [ERROR] : [bleServerLogger] : [bleReceiver.py] : [acceptBluetoothConnection] : Failed to accept bluetooth connection ... 
Traceback (most recent call last):
  File "bleReceiver.py", line 86, in acceptBluetoothConnection
    self.clientSocket, clientInfo = self.serverSocket.accept()
  File "/usr/lib/python2.7/dist-packages/bluetooth/bluez.py", line 129, in accept
    client, addr = self._sock.accept ()
KeyboardInterrupt
[2019-10-16 13:33:10,260] : [ERROR] : [bleServerLogger] : [bleReceiver.py] : [deserializedData] : Failed to de-serialized string ... 
Traceback (most recent call last):
  File "bleReceiver.py", line 113, in deserializedData
    self.dataObj=pickle.loads(_dataRecv)
TypeError: loads() argument 1 must be string, not None
[2019-10-16 13:33:10,266] : [ERROR] : [bleServerLogger] : [bleReceiver.py] : [closeBluetoothSocket] : Failed to close the bluetooth sockets 
Traceback (most recent call last):
  File "bleReceiver.py", line 135, in closeBluetoothSocket
    self.clientSocket.close()
AttributeError: 'NoneType' object has no attribute 'close'
[2019-10-16 13:45:02,697] : [ERROR] : [bleServerLogger] : [bleReceiver.py] : [acceptBluetoothConnection] : Failed to accept bluetooth connection ... 
Traceback (most recent call last):
  File "bleReceiver.py", line 86, in acceptBluetoothConnection
    self.clientSocket, clientInfo = self.serverSocket.accept()
  File "/usr/lib/python2.7/dist-packages/bluetooth/bluez.py", line 129, in accept
    client, addr = self._sock.accept ()
KeyboardInterrupt
[2019-10-16 13:45:02,698] : [ERROR] : [bleServerLogger] : [bleReceiver.py] : [deserializedData] : Failed to de-serialized string ... 
Traceback (most recent call last):
  File "bleReceiver.py", line 113, in deserializedData
    self.dataObj=pickle.loads(_dataRecv)
TypeError: loads() argument 1 must be string, not None
[2019-10-16 13:45:02,699] : [ERROR] : [bleServerLogger] : [bleReceiver.py] : [closeBluetoothSocket] : Failed to close the bluetooth sockets 
Traceback (most recent call last):
  File "bleReceiver.py", line 135, in closeBluetoothSocket
    self.clientSocket.close()
AttributeError: 'NoneType' object has no attribute 'close'
[2019-10-16 13:49:05,480] : [ERROR] : [bleServerLogger] : [bleReceiver.py] : [acceptBluetoothConnection] : Failed to accept bluetooth connection ... 
Traceback (most recent call last):
  File "bleReceiver.py", line 86, in acceptBluetoothConnection
    self.clientSocket, clientInfo = self.serverSocket.accept()
  File "/usr/lib/python2.7/dist-packages/bluetooth/bluez.py", line 129, in accept
    client, addr = self._sock.accept ()
KeyboardInterrupt
[2019-10-16 13:49:05,484] : [ERROR] : [bleServerLogger] : [bleReceiver.py] : [deserializedData] : Failed to de-serialized string ... 
Traceback (most recent call last):
  File "bleReceiver.py", line 113, in deserializedData
    self.dataObj=pickle.loads(_dataRecv)
TypeError: loads() argument 1 must be string, not None
[2019-10-16 13:49:05,491] : [ERROR] : [bleServerLogger] : [bleReceiver.py] : [closeBluetoothSocket] : Failed to close the bluetooth sockets 
Traceback (most recent call last):
  File "bleReceiver.py", line 135, in closeBluetoothSocket
    self.clientSocket.close()
AttributeError: 'NoneType' object has no attribute 'close'
[2019-10-16 13:50:31,231] : [ERROR] : [bleServerLogger] : [bleReceiver.py] : [acceptBluetoothConnection] : Failed to accept bluetooth connection ... 
Traceback (most recent call last):
  File "bleReceiver.py", line 86, in acceptBluetoothConnection
    self.clientSocket, clientInfo = self.serverSocket.accept()
  File "/usr/lib/python2.7/dist-packages/bluetooth/bluez.py", line 129, in accept
    client, addr = self._sock.accept ()
KeyboardInterrupt
[2019-10-16 13:50:31,236] : [ERROR] : [bleServerLogger] : [bleReceiver.py] : [deserializedData] : Failed to de-serialized string ... 
Traceback (most recent call last):
  File "bleReceiver.py", line 113, in deserializedData
    self.dataObj=pickle.loads(_dataRecv)
TypeError: loads() argument 1 must be string, not None
[2019-10-16 13:50:31,241] : [ERROR] : [bleServerLogger] : [bleReceiver.py] : [closeBluetoothSocket] : Failed to close the bluetooth sockets 
Traceback (most recent call last):
  File "bleReceiver.py", line 135, in closeBluetoothSocket
    self.clientSocket.close()
AttributeError: 'NoneType' object has no attribute 'close'
[2019-10-16 14:04:46,939] : [ERROR] : [bleServerLogger] : [bleReceiver.py] : [advertiseBluetoothService] : Failed to advertise bluetooth services  ... 
Traceback (most recent call last):
  File "bleReceiver.py", line 74, in advertiseBluetoothService
    advertise_service( self.serverSocket, self.serviceName,
AttributeError: bleServer instance has no attribute 'serviceName'
[2019-10-16 14:06:08,378] : [ERROR] : [bleServerLogger] : [bleReceiver.py] : [acceptBluetoothConnection] : Failed to accept bluetooth connection ... 
Traceback (most recent call last):
  File "bleReceiver.py", line 86, in acceptBluetoothConnection
    self.clientSocket, clientInfo = self.serverSocket.accept()
  File "/usr/lib/python2.7/dist-packages/bluetooth/bluez.py", line 129, in accept
    client, addr = self._sock.accept ()
KeyboardInterrupt
[2019-10-16 14:06:08,383] : [ERROR] : [bleServerLogger] : [bleReceiver.py] : [deserializedData] : Failed to de-serialized string ... 
Traceback (most recent call last):
  File "bleReceiver.py", line 113, in deserializedData
    self.dataObj=pickle.loads(_dataRecv)
TypeError: loads() argument 1 must be string, not None
[2019-10-16 14:06:08,385] : [ERROR] : [bleServerLogger] : [bleReceiver.py] : [writeJsonFile] : Failed to write json contents to the file ... 
Traceback (most recent call last):
  File "bleReceiver.py", line 121, in writeJsonFile
    jsonFileObj = open(self.jsonFile,"w")
AttributeError: bleServer instance has no attribute 'jsonFile'
[2019-10-16 14:06:08,388] : [ERROR] : [bleServerLogger] : [bleReceiver.py] : [closeBluetoothSocket] : Failed to close the bluetooth sockets 
Traceback (most recent call last):
  File "bleReceiver.py", line 135, in closeBluetoothSocket
    self.clientSocket.close()
AttributeError: 'int' object has no attribute 'close'
[2019-10-16 14:06:09,471] : [ERROR] : [bleServerLogger] : [bleReceiver.py] : [advertiseBluetoothService] : Failed to advertise bluetooth services  ... 
Traceback (most recent call last):
  File "bleReceiver.py", line 74, in advertiseBluetoothService
    advertise_service( self.serverSocket, self.serviceName,
AttributeError: bleServer instance has no attribute 'serviceName'
[2019-10-16 14:08:44,578] : [ERROR] : [bleServerLogger] : [bleReceiver.py] : [acceptBluetoothConnection] : Failed to accept bluetooth connection ... 
Traceback (most recent call last):
  File "bleReceiver.py", line 86, in acceptBluetoothConnection
    self.clientSocket, clientInfo = self.serverSocket.accept()
  File "/usr/lib/python2.7/dist-packages/bluetooth/bluez.py", line 129, in accept
    client, addr = self._sock.accept ()
KeyboardInterrupt
[2019-10-16 14:08:44,582] : [ERROR] : [bleServerLogger] : [bleReceiver.py] : [deserializedData] : Failed to de-serialized string ... 
Traceback (most recent call last):
  File "bleReceiver.py", line 113, in deserializedData
    self.dataObj=pickle.loads(_dataRecv)
TypeError: loads() argument 1 must be string, not None
[2019-10-16 14:08:44,584] : [ERROR] : [bleServerLogger] : [bleReceiver.py] : [writeJsonFile] : Failed to write json contents to the file ... 
Traceback (most recent call last):
  File "bleReceiver.py", line 121, in writeJsonFile
    jsonFileObj = open(self.jsonFile,"w")
AttributeError: bleServer instance has no attribute 'jsonFile'
[2019-10-16 14:08:44,586] : [ERROR] : [bleServerLogger] : [bleReceiver.py] : [closeBluetoothSocket] : Failed to close the bluetooth sockets 
Traceback (most recent call last):
  File "bleReceiver.py", line 135, in closeBluetoothSocket
    self.clientSocket.close()
AttributeError: 'int' object has no attribute 'close'
[2019-10-16 14:12:35,736] : [ERROR] : [bleServerLogger] : [bleReceiver.py] : [advertiseBluetoothService] : Failed to advertise bluetooth services  ... 
Traceback (most recent call last):
  File "bleReceiver.py", line 74, in advertiseBluetoothService
    advertise_service( self.serverSocket, self.serviceName,
AttributeError: bleServer instance has no attribute 'serviceName'
[2019-10-16 14:19:58,558] : [ERROR] : [bleServerLogger] : [bleReceiver.py] : [acceptBluetoothConnection] : Failed to accept bluetooth connection ... 
Traceback (most recent call last):
  File "bleReceiver.py", line 86, in acceptBluetoothConnection
    self.clientSocket, clientInfo = self.serverSocket.accept()
  File "/usr/lib/python2.7/dist-packages/bluetooth/bluez.py", line 129, in accept
    client, addr = self._sock.accept ()
KeyboardInterrupt
[2019-10-16 14:19:58,561] : [ERROR] : [bleServerLogger] : [bleReceiver.py] : [deserializedData] : Failed to de-serialized string ... 
Traceback (most recent call last):
  File "bleReceiver.py", line 113, in deserializedData
    self.dataObj=pickle.loads(_dataRecv)
TypeError: loads() argument 1 must be string, not None
[2019-10-16 14:19:58,563] : [ERROR] : [bleServerLogger] : [bleReceiver.py] : [writeJsonFile] : Failed to write json contents to the file ... 
Traceback (most recent call last):
  File "bleReceiver.py", line 121, in writeJsonFile
    jsonFileObj = open(self.jsonFile,"w")
AttributeError: bleServer instance has no attribute 'jsonFile'
[2019-10-16 14:19:58,565] : [ERROR] : [bleServerLogger] : [bleReceiver.py] : [closeBluetoothSocket] : Failed to close the bluetooth sockets 
Traceback (most recent call last):
  File "bleReceiver.py", line 135, in closeBluetoothSocket
    self.clientSocket.close()
AttributeError: 'int' object has no attribute 'close'
[2019-10-16 14:20:34,704] : [ERROR] : [bleServerLogger] : [bleReceiver.py] : [advertiseBluetoothService] : Failed to advertise bluetooth services  ... 
Traceback (most recent call last):
  File "bleReceiver.py", line 74, in advertiseBluetoothService
    advertise_service( self.serverSocket, self.serviceName,
AttributeError: bleServer instance has no attribute 'serviceName'
[2019-10-16 14:23:28,169] : [ERROR] : [bleServerLogger] : [bleReceiver.py] : [acceptBluetoothConnection] : Failed to accept bluetooth connection ... 
Traceback (most recent call last):
  File "bleReceiver.py", line 86, in acceptBluetoothConnection
    self.clientSocket, clientInfo = self.serverSocket.accept()
  File "/usr/lib/python2.7/dist-packages/bluetooth/bluez.py", line 129, in accept
    client, addr = self._sock.accept ()
KeyboardInterrupt
[2019-10-16 14:23:28,171] : [ERROR] : [bleServerLogger] : [bleReceiver.py] : [deserializedData] : Failed to de-serialized string ... 
Traceback (most recent call last):
  File "bleReceiver.py", line 113, in deserializedData
    self.dataObj=pickle.loads(_dataRecv)
TypeError: loads() argument 1 must be string, not None
[2019-10-16 14:23:28,173] : [ERROR] : [bleServerLogger] : [bleReceiver.py] : [writeJsonFile] : Failed to write json contents to the file ... 
Traceback (most recent call last):
  File "bleReceiver.py", line 121, in writeJsonFile
    jsonFileObj = open(self.jsonFile,"w")
AttributeError: bleServer instance has no attribute 'jsonFile'
[2019-10-16 14:23:28,174] : [ERROR] : [bleServerLogger] : [bleReceiver.py] : [closeBluetoothSocket] : Failed to close the bluetooth sockets 
Traceback (most recent call last):
  File "bleReceiver.py", line 135, in closeBluetoothSocket
    self.clientSocket.close()
AttributeError: 'int' object has no attribute 'close'
[2019-10-16 14:23:28,949] : [ERROR] : [bleServerLogger] : [bleReceiver.py] : [advertiseBluetoothService] : Failed to advertise bluetooth services  ... 
Traceback (most recent call last):
  File "bleReceiver.py", line 74, in advertiseBluetoothService
    advertise_service( self.serverSocket, self.serviceName,
AttributeError: bleServer instance has no attribute 'serviceName'
[2019-10-16 14:31:52,693] : [ERROR] : [bleServerLogger] : [bleReceiver.py] : [acceptBluetoothConnection] : Failed to accept bluetooth connection ... 
Traceback (most recent call last):
  File "bleReceiver.py", line 86, in acceptBluetoothConnection
    self.clientSocket, clientInfo = self.serverSocket.accept()
  File "/usr/lib/python2.7/dist-packages/bluetooth/bluez.py", line 129, in accept
    client, addr = self._sock.accept ()
KeyboardInterrupt
[2019-10-16 14:31:52,697] : [ERROR] : [bleServerLogger] : [bleReceiver.py] : [deserializedData] : Failed to de-serialized string ... 
Traceback (most recent call last):
  File "bleReceiver.py", line 113, in deserializedData
    self.dataObj=pickle.loads(_dataRecv)
TypeError: loads() argument 1 must be string, not None
[2019-10-16 14:31:52,699] : [ERROR] : [bleServerLogger] : [bleReceiver.py] : [writeJsonFile] : Failed to write json contents to the file ... 
Traceback (most recent call last):
  File "bleReceiver.py", line 121, in writeJsonFile
    jsonFileObj = open(self.jsonFile,"w")
AttributeError: bleServer instance has no attribute 'jsonFile'
[2019-10-16 14:31:52,701] : [ERROR] : [bleServerLogger] : [bleReceiver.py] : [closeBluetoothSocket] : Failed to close the bluetooth sockets 
Traceback (most recent call last):
  File "bleReceiver.py", line 135, in closeBluetoothSocket
    self.clientSocket.close()
AttributeError: 'int' object has no attribute 'close'
[2019-10-16 14:31:55,545] : [ERROR] : [bleServerLogger] : [bleReceiver.py] : [acceptBluetoothConnection] : Failed to accept bluetooth connection ... 
Traceback (most recent call last):
  File "bleReceiver.py", line 86, in acceptBluetoothConnection
    self.clientSocket, clientInfo = self.serverSocket.accept()
  File "/usr/lib/python2.7/dist-packages/bluetooth/bluez.py", line 129, in accept
    client, addr = self._sock.accept ()
KeyboardInterrupt
[2019-10-16 14:31:55,549] : [ERROR] : [bleServerLogger] : [bleReceiver.py] : [deserializedData] : Failed to de-serialized string ... 
Traceback (most recent call last):
  File "bleReceiver.py", line 113, in deserializedData
    self.dataObj=pickle.loads(_dataRecv)
TypeError: loads() argument 1 must be string, not None
[2019-10-16 14:31:55,554] : [ERROR] : [bleServerLogger] : [bleReceiver.py] : [closeBluetoothSocket] : Failed to close the bluetooth sockets 
Traceback (most recent call last):
  File "bleReceiver.py", line 135, in closeBluetoothSocket
    self.clientSocket.close()
AttributeError: 'NoneType' object has no attribute 'close'
[2019-10-16 14:32:58,113] : [ERROR] : [bleServerLogger] : [bleReceiver.py] : [acceptBluetoothConnection] : Failed to accept bluetooth connection ... 
Traceback (most recent call last):
  File "bleReceiver.py", line 86, in acceptBluetoothConnection
    self.clientSocket, clientInfo = self.serverSocket.accept()
  File "/usr/lib/python2.7/dist-packages/bluetooth/bluez.py", line 129, in accept
    client, addr = self._sock.accept ()
KeyboardInterrupt
[2019-10-16 14:32:58,118] : [ERROR] : [bleServerLogger] : [bleReceiver.py] : [deserializedData] : Failed to de-serialized string ... 
Traceback (most recent call last):
  File "bleReceiver.py", line 113, in deserializedData
    self.dataObj=pickle.loads(_dataRecv)
TypeError: loads() argument 1 must be string, not None
[2019-10-16 14:32:58,123] : [ERROR] : [bleServerLogger] : [bleReceiver.py] : [closeBluetoothSocket] : Failed to close the bluetooth sockets 
Traceback (most recent call last):
  File "bleReceiver.py", line 135, in closeBluetoothSocket
    self.clientSocket.close()
AttributeError: 'int' object has no attribute 'close'
[2019-10-16 14:35:17,577] : [ERROR] : [bleServerLogger] : [bleReceiver.py] : [acceptBluetoothConnection] : Failed to accept bluetooth connection ... 
Traceback (most recent call last):
  File "bleReceiver.py", line 86, in acceptBluetoothConnection
    self.clientSocket, clientInfo = self.serverSocket.accept()
  File "/usr/lib/python2.7/dist-packages/bluetooth/bluez.py", line 129, in accept
    client, addr = self._sock.accept ()
KeyboardInterrupt
[2019-10-16 14:35:17,578] : [ERROR] : [bleServerLogger] : [bleReceiver.py] : [deserializedData] : Failed to de-serialized string ... 
Traceback (most recent call last):
  File "bleReceiver.py", line 113, in deserializedData
    self.dataObj=pickle.loads(_dataRecv)
TypeError: loads() argument 1 must be string, not None
[2019-10-16 14:35:17,579] : [ERROR] : [bleServerLogger] : [bleReceiver.py] : [closeBluetoothSocket] : Failed to close the bluetooth sockets 
Traceback (most recent call last):
  File "bleReceiver.py", line 135, in closeBluetoothSocket
    self.clientSocket.close()
AttributeError: 'int' object has no attribute 'close'
[2019-10-16 15:18:02,258] : [ERROR] : [bleServerLogger] : [bleReceiver.py] : [deserializedData] : Failed to de-serialized string ... 
Traceback (most recent call last):
  File "bleReceiver.py", line 117, in deserializedData
    self.dataObj=pickle.loads(_dataRecv)
TypeError: loads() argument 1 must be string, not None
[2019-10-29 18:33:12,767] : [ERROR] : [bleClientLogger] : [bleSender.py] : [getBluetoothServices] : Couldn't find the RaspberryPi Bluetooth service : Invalid uuid
Traceback (most recent call last):
  File "bleSender.py", line 59, in getBluetoothServices
    if not bleService: raise SystemExit(), None
SystemExit
[2019-10-30 11:16:46,932] : [ERROR] : [bleClientLogger] : [bleSender.py] : [getBluetoothServices] : Couldn't find the RaspberryPi Bluetooth service : Invalid uuid
Traceback (most recent call last):
  File "bleSender.py", line 64, in getBluetoothServices
    raise SystemExit(), None
SystemExit
[2019-10-30 11:16:46,936] : [ERROR] : [bleClientLogger] : [bleSender.py] : [getBluetoothConnection] : Failed to connect to BLAH BLAH
[2019-10-30 11:16:46,947] : [ERROR] : [bleClientLogger] : [bleSender.py] : [sendData] : Failed to send data over bluetooth connection
Traceback (most recent call last):
  File "bleSender.py", line 120, in sendData
    self.clientSocket.send(_serializedData)
  File "<string>", line 5, in send
BluetoothError: (107, 'Transport endpoint is not connected')
[2019-10-30 11:19:40,738] : [ERROR] : [bleClientLogger] : [bleSender.py] : [getBluetoothServices] : Couldn't find the RaspberryPi Bluetooth service : Invalid uuid
Traceback (most recent call last):
  File "bleSender.py", line 64, in getBluetoothServices
    raise SystemExit(), None
SystemExit
[2019-10-30 11:19:40,741] : [ERROR] : [bleClientLogger] : [bleSender.py] : [getBluetoothConnection] : Failed to connect to BLAH BLAH
[2019-10-30 11:19:40,745] : [ERROR] : [bleClientLogger] : [bleSender.py] : [sendData] : Failed to send data over bluetooth connection
Traceback (most recent call last):
  File "bleSender.py", line 120, in sendData
    self.clientSocket.send(_serializedData)
  File "<string>", line 5, in send
BluetoothError: (107, 'Transport endpoint is not connected')
[2019-10-30 11:20:32,938] : [ERROR] : [bleClientLogger] : [bleSender.py] : [getBluetoothServices] : Couldn't find the RaspberryPi Bluetooth service : Invalid uuid
Traceback (most recent call last):
  File "bleSender.py", line 64, in getBluetoothServices
    raise SystemExit(), None
SystemExit
[2019-10-30 11:20:32,940] : [ERROR] : [bleClientLogger] : [bleSender.py] : [getBluetoothConnection] : Failed to connect to BLAH BLAH
[2019-10-30 11:20:32,947] : [ERROR] : [bleClientLogger] : [bleSender.py] : [sendData] : Failed to send data over bluetooth connection
Traceback (most recent call last):
  File "bleSender.py", line 120, in sendData
    self.clientSocket.send(_serializedData)
  File "<string>", line 5, in send
BluetoothError: (107, 'Transport endpoint is not connected')
[2019-10-30 11:22:08,521] : [ERROR] : [bleClientLogger] : [bleSender.py] : [getBluetoothServices] : Couldn't find the RaspberryPi Bluetooth service : Invalid uuid
Traceback (most recent call last):
  File "bleSender.py", line 64, in getBluetoothServices
    raise SystemExit(), None
SystemExit
[2019-10-30 11:22:08,525] : [ERROR] : [bleClientLogger] : [bleSender.py] : [getBluetoothConnection] : Failed to connect to BLAH BLAH
[2019-10-30 11:22:08,532] : [ERROR] : [bleClientLogger] : [bleSender.py] : [sendData] : Failed to send data over bluetooth connection
Traceback (most recent call last):
  File "bleSender.py", line 120, in sendData
    self.clientSocket.send(_serializedData)
  File "<string>", line 5, in send
BluetoothError: (107, 'Transport endpoint is not connected')
[2019-10-30 11:24:03,180] : [ERROR] : [bleClientLogger] : [bleSender.py] : [getBluetoothServices] : Couldn't find the RaspberryPi Bluetooth service : Invalid uuid
Traceback (most recent call last):
  File "bleSender.py", line 64, in getBluetoothServices
    raise SystemExit(), None
SystemExit
[2019-10-30 11:24:03,186] : [ERROR] : [bleClientLogger] : [bleSender.py] : [getBluetoothConnection] : Failed to connect to BLAH BLAH
[2019-10-30 11:24:03,206] : [ERROR] : [bleClientLogger] : [bleSender.py] : [sendData] : Failed to send data over bluetooth connection
Traceback (most recent call last):
  File "bleSender.py", line 120, in sendData
    self.clientSocket.send(_serializedData)
  File "<string>", line 5, in send
BluetoothError: (107, 'Transport endpoint is not connected')
[2019-10-30 11:30:07,978] : [ERROR] : [bleServerLogger] : [bleReceiver.py] : [acceptBluetoothConnection] : Failed to accept bluetooth connection ... 
Traceback (most recent call last):
  File "bleReceiver.py", line 90, in acceptBluetoothConnection
    self.clientSocket, clientInfo = self.serverSocket.accept()
  File "/usr/lib/python2.7/dist-packages/bluetooth/bluez.py", line 129, in accept
    client, addr = self._sock.accept ()
KeyboardInterrupt
[2019-10-30 11:30:07,983] : [ERROR] : [bleServerLogger] : [bleReceiver.py] : [deserializedData] : Failed to de-serialized string ... 
Traceback (most recent call last):
  File "bleReceiver.py", line 117, in deserializedData
    self.dataObj=pickle.loads(_dataRecv)
TypeError: loads() argument 1 must be string, not None
[2019-10-30 11:30:07,987] : [ERROR] : [bleServerLogger] : [bleReceiver.py] : [closeBluetoothSocket] : Failed to close the bluetooth sockets 
Traceback (most recent call last):
  File "bleReceiver.py", line 139, in closeBluetoothSocket
    self.clientSocket.close()
AttributeError: 'NoneType' object has no attribute 'close'
[2019-10-30 11:31:59,079] : [ERROR] : [bleServerLogger] : [bleReceiver.py] : [acceptBluetoothConnection] : Failed to accept bluetooth connection ... 
Traceback (most recent call last):
  File "bleReceiver.py", line 90, in acceptBluetoothConnection
    self.clientSocket, clientInfo = self.serverSocket.accept()
  File "/usr/lib/python2.7/dist-packages/bluetooth/bluez.py", line 129, in accept
    client, addr = self._sock.accept ()
KeyboardInterrupt
[2019-10-30 11:31:59,082] : [ERROR] : [bleServerLogger] : [bleReceiver.py] : [deserializedData] : Failed to de-serialized string ... 
Traceback (most recent call last):
  File "bleReceiver.py", line 117, in deserializedData
    self.dataObj=pickle.loads(_dataRecv)
TypeError: loads() argument 1 must be string, not None
[2019-10-30 11:31:59,086] : [ERROR] : [bleServerLogger] : [bleReceiver.py] : [closeBluetoothSocket] : Failed to close the bluetooth sockets 
Traceback (most recent call last):
  File "bleReceiver.py", line 139, in closeBluetoothSocket
    self.clientSocket.close()
AttributeError: 'NoneType' object has no attribute 'close'
[2019-10-30 12:01:34,370] : [ERROR] : [bleServerLogger] : [bleReceiver.py] : [acceptBluetoothConnection] : Failed to accept bluetooth connection ... 
Traceback (most recent call last):
  File "bleReceiver.py", line 90, in acceptBluetoothConnection
    self.clientSocket, clientInfo = self.serverSocket.accept()
  File "/usr/lib/python2.7/dist-packages/bluetooth/bluez.py", line 129, in accept
    client, addr = self._sock.accept ()
KeyboardInterrupt
[2019-10-30 12:01:34,374] : [ERROR] : [bleServerLogger] : [bleReceiver.py] : [deserializedData] : Failed to de-serialized string ... 
Traceback (most recent call last):
  File "bleReceiver.py", line 117, in deserializedData
    self.dataObj=pickle.loads(_dataRecv)
TypeError: loads() argument 1 must be string, not None
[2019-10-30 12:01:34,381] : [ERROR] : [bleServerLogger] : [bleReceiver.py] : [closeBluetoothSocket] : Failed to close the bluetooth sockets 
Traceback (most recent call last):
  File "bleReceiver.py", line 139, in closeBluetoothSocket
    self.clientSocket.close()
AttributeError: 'NoneType' object has no attribute 'close'
[2019-10-30 12:01:50,656] : [ERROR] : [bleClientLogger] : [bleSender.py] : [getBluetoothServices] : Couldn't find the RaspberryPi Bluetooth service : Invalid uuid
Traceback (most recent call last):
  File "bleSender.py", line 53, in getBluetoothServices
    bleService = find_service( uuid = self.uuid, address = self.addr )
  File "/usr/lib/python2.7/dist-packages/bluetooth/bluez.py", line 186, in find_service
    devices = discover_devices ()
  File "/usr/lib/python2.7/dist-packages/bluetooth/bluez.py", line 19, in discover_devices
    results = _bt.hci_inquiry (sock, duration=duration, flush_cache=True)
KeyboardInterrupt
[2019-10-30 12:01:50,663] : [ERROR] : [bleClientLogger] : [bleSender.py] : [getBluetoothConnection] : Failed to connect to BLAH BLAH
[2019-10-30 12:01:50,672] : [ERROR] : [bleClientLogger] : [bleSender.py] : [sendData] : Failed to send data over bluetooth connection
Traceback (most recent call last):
  File "bleSender.py", line 120, in sendData
    self.clientSocket.send(_serializedData)
  File "<string>", line 5, in send
BluetoothError: (107, 'Transport endpoint is not connected')
[2019-10-30 13:20:37,305] : [ERROR] : [bleClientLogger] : [bleSender.py] : [getBluetoothServices] : Couldn't find the RaspberryPi Bluetooth service : Invalid uuid
Traceback (most recent call last):
  File "bleSender.py", line 53, in getBluetoothServices
    bleService = find_service( uuid = self.uuid, address = self.addr )
  File "/usr/lib/python2.7/dist-packages/bluetooth/bluez.py", line 199, in find_service
    s.connect (addr)
KeyboardInterrupt
[2019-10-30 13:20:37,313] : [ERROR] : [bleClientLogger] : [bleSender.py] : [getBluetoothConnection] : Failed to connect to BLAH BLAH
[2019-10-30 13:20:37,317] : [ERROR] : [bleClientLogger] : [bleSender.py] : [sendData] : Failed to send data over bluetooth connection
Traceback (most recent call last):
  File "bleSender.py", line 120, in sendData
    self.clientSocket.send(_serializedData)
  File "<string>", line 5, in send
BluetoothError: (107, 'Transport endpoint is not connected')
[2019-10-30 13:22:22,081] : [ERROR] : [bleClientLogger] : [bleSender.py] : [getBluetoothServices] : Couldn't find the RaspberryPi Bluetooth service : Invalid uuid
Traceback (most recent call last):
  File "bleSender.py", line 64, in getBluetoothServices
    raise SystemExit(), None
SystemExit
[2019-10-30 13:22:22,099] : [ERROR] : [bleClientLogger] : [bleSender.py] : [getBluetoothConnection] : Failed to connect to BLAH BLAH
[2019-10-30 13:22:22,105] : [ERROR] : [bleClientLogger] : [bleSender.py] : [sendData] : Failed to send data over bluetooth connection
Traceback (most recent call last):
  File "bleSender.py", line 120, in sendData
    self.clientSocket.send(_serializedData)
  File "<string>", line 5, in send
BluetoothError: (107, 'Transport endpoint is not connected')
[2019-10-30 13:23:52,318] : [ERROR] : [bleClientLogger] : [bleSender.py] : [getBluetoothServices] : Couldn't find the RaspberryPi Bluetooth service : Invalid uuid
Traceback (most recent call last):
  File "bleSender.py", line 53, in getBluetoothServices
    bleService = find_service( uuid = self.uuid, address = self.addr )
  File "/usr/lib/python2.7/dist-packages/bluetooth/bluez.py", line 186, in find_service
    devices = discover_devices ()
  File "/usr/lib/python2.7/dist-packages/bluetooth/bluez.py", line 19, in discover_devices
    results = _bt.hci_inquiry (sock, duration=duration, flush_cache=True)
KeyboardInterrupt
[2019-10-30 13:23:52,325] : [ERROR] : [bleClientLogger] : [bleSender.py] : [getBluetoothConnection] : Failed to connect to BLAH BLAH
[2019-10-30 13:23:52,332] : [ERROR] : [bleClientLogger] : [bleSender.py] : [sendData] : Failed to send data over bluetooth connection
Traceback (most recent call last):
  File "bleSender.py", line 120, in sendData
    self.clientSocket.send(_serializedData)
  File "<string>", line 5, in send
BluetoothError: (107, 'Transport endpoint is not connected')
[2019-10-30 13:26:09,535] : [ERROR] : [bleClientLogger] : [bleSender.py] : [getBluetoothServices] : Couldn't find the RaspberryPi Bluetooth service : Invalid uuid
Traceback (most recent call last):
  File "bleSender.py", line 64, in getBluetoothServices
    raise SystemExit(), None
SystemExit
[2019-10-30 13:26:09,541] : [ERROR] : [bleClientLogger] : [bleSender.py] : [getBluetoothConnection] : Failed to connect to BLAH BLAH
[2019-10-30 13:26:09,548] : [ERROR] : [bleClientLogger] : [bleSender.py] : [sendData] : Failed to send data over bluetooth connection
Traceback (most recent call last):
  File "bleSender.py", line 120, in sendData
    self.clientSocket.send(_serializedData)
  File "<string>", line 5, in send
BluetoothError: (107, 'Transport endpoint is not connected')
[2019-10-30 13:49:43,744] : [ERROR] : [bleClientLogger] : [bleSender.py] : [getBluetoothServices] : Couldn't find the RaspberryPi Bluetooth service : Invalid uuid
Traceback (most recent call last):
  File "bleSender.py", line 64, in getBluetoothServices
    raise SystemExit(), None
SystemExit
[2019-10-30 13:49:43,746] : [ERROR] : [bleClientLogger] : [bleSender.py] : [getBluetoothConnection] : Failed to connect to BLAH BLAH
[2019-10-30 13:49:43,750] : [ERROR] : [bleClientLogger] : [bleSender.py] : [sendData] : Failed to send data over bluetooth connection
Traceback (most recent call last):
  File "bleSender.py", line 120, in sendData
    self.clientSocket.send(_serializedData)
  File "<string>", line 5, in send
BluetoothError: (107, 'Transport endpoint is not connected')
[2019-10-30 13:59:04,887] : [ERROR] : [bleClientLogger] : [bleSender.py] : [getBluetoothServices] : Couldn't find the RaspberryPi Bluetooth service : Invalid uuid
Traceback (most recent call last):
  File "bleSender.py", line 53, in getBluetoothServices
    bleService = find_service( name = "MyPi",uuid = self.uuid, address = self.addr )
  File "/usr/lib/python2.7/dist-packages/bluetooth/bluez.py", line 186, in find_service
    devices = discover_devices ()
  File "/usr/lib/python2.7/dist-packages/bluetooth/bluez.py", line 19, in discover_devices
    results = _bt.hci_inquiry (sock, duration=duration, flush_cache=True)
KeyboardInterrupt
[2019-10-30 13:59:04,894] : [ERROR] : [bleClientLogger] : [bleSender.py] : [getBluetoothConnection] : Failed to connect to BLAH BLAH
[2019-10-30 13:59:04,901] : [ERROR] : [bleClientLogger] : [bleSender.py] : [sendData] : Failed to send data over bluetooth connection
Traceback (most recent call last):
  File "bleSender.py", line 120, in sendData
    self.clientSocket.send(_serializedData)
  File "<string>", line 5, in send
BluetoothError: (107, 'Transport endpoint is not connected')
[2019-10-30 14:04:11,867] : [ERROR] : [bleClientLogger] : [bleSender.py] : [getBluetoothServices] : Couldn't find the RaspberryPi Bluetooth service : Invalid uuid
Traceback (most recent call last):
  File "bleSender.py", line 64, in getBluetoothServices
    raise SystemExit(), None
SystemExit
[2019-10-30 14:04:11,878] : [ERROR] : [bleClientLogger] : [bleSender.py] : [getBluetoothConnection] : Failed to connect to BLAH BLAH
[2019-10-30 14:04:11,886] : [ERROR] : [bleClientLogger] : [bleSender.py] : [sendData] : Failed to send data over bluetooth connection
Traceback (most recent call last):
  File "bleSender.py", line 120, in sendData
    self.clientSocket.send(_serializedData)
  File "<string>", line 5, in send
BluetoothError: (107, 'Transport endpoint is not connected')
[2019-10-30 14:09:07,146] : [ERROR] : [bleClientLogger] : [bleSender.py] : [getBluetoothServices] : Couldn't find the RaspberryPi Bluetooth service : Invalid uuid
Traceback (most recent call last):
  File "bleSender.py", line 53, in getBluetoothServices
    bleService = find_service( uuid = self.uuid, address = self.addr )
  File "/usr/lib/python2.7/dist-packages/bluetooth/bluez.py", line 186, in find_service
    devices = discover_devices ()
  File "/usr/lib/python2.7/dist-packages/bluetooth/bluez.py", line 19, in discover_devices
    results = _bt.hci_inquiry (sock, duration=duration, flush_cache=True)
KeyboardInterrupt
[2019-10-30 14:09:07,151] : [ERROR] : [bleClientLogger] : [bleSender.py] : [getBluetoothConnection] : Failed to connect to BLAH BLAH
[2019-10-30 14:09:07,157] : [ERROR] : [bleClientLogger] : [bleSender.py] : [sendData] : Failed to send data over bluetooth connection
Traceback (most recent call last):
  File "bleSender.py", line 120, in sendData
    self.clientSocket.send(_serializedData)
  File "<string>", line 5, in send
BluetoothError: (107, 'Transport endpoint is not connected')
[2019-10-30 14:11:20,637] : [ERROR] : [bleClientLogger] : [bleSender.py] : [getBluetoothServices] : Couldn't find the RaspberryPi Bluetooth service : Invalid uuid
Traceback (most recent call last):
  File "bleSender.py", line 64, in getBluetoothServices
    raise SystemExit(), None
SystemExit
[2019-10-30 14:11:20,641] : [ERROR] : [bleClientLogger] : [bleSender.py] : [getBluetoothConnection] : Failed to connect to BLAH BLAH
[2019-10-30 14:11:20,647] : [ERROR] : [bleClientLogger] : [bleSender.py] : [sendData] : Failed to send data over bluetooth connection
Traceback (most recent call last):
  File "bleSender.py", line 120, in sendData
    self.clientSocket.send(_serializedData)
  File "<string>", line 5, in send
BluetoothError: (107, 'Transport endpoint is not connected')
[2019-10-30 14:21:33,785] : [ERROR] : [bleClientLogger] : [bleSender.py] : [getBluetoothServices] : Couldn't find the RaspberryPi Bluetooth service : Invalid uuid
Traceback (most recent call last):
  File "bleSender.py", line 64, in getBluetoothServices
    raise SystemExit(), None
SystemExit
[2019-10-30 14:21:33,791] : [ERROR] : [bleClientLogger] : [bleSender.py] : [getBluetoothConnection] : Failed to connect to BLAH BLAH
[2019-10-30 14:21:33,805] : [ERROR] : [bleClientLogger] : [bleSender.py] : [sendData] : Failed to send data over bluetooth connection
Traceback (most recent call last):
  File "bleSender.py", line 120, in sendData
    self.clientSocket.send(_serializedData)
  File "<string>", line 5, in send
BluetoothError: (107, 'Transport endpoint is not connected')
[2019-10-30 14:23:50,008] : [ERROR] : [bleClientLogger] : [bleSender.py] : [getBluetoothServices] : Couldn't find the RaspberryPi Bluetooth service : Invalid uuid
Traceback (most recent call last):
  File "bleSender.py", line 53, in getBluetoothServices
    bleService = find_service( uuid = self.uuid, address = self.addr )
  File "/usr/lib/python2.7/dist-packages/bluetooth/bluez.py", line 199, in find_service
    s.connect (addr)
KeyboardInterrupt
[2019-10-30 14:23:50,012] : [ERROR] : [bleClientLogger] : [bleSender.py] : [getBluetoothConnection] : Failed to connect to BLAH BLAH
[2019-10-30 14:23:50,018] : [ERROR] : [bleClientLogger] : [bleSender.py] : [sendData] : Failed to send data over bluetooth connection
Traceback (most recent call last):
  File "bleSender.py", line 120, in sendData
    self.clientSocket.send(_serializedData)
  File "<string>", line 5, in send
BluetoothError: (107, 'Transport endpoint is not connected')
[2019-10-30 14:24:58,931] : [ERROR] : [bleClientLogger] : [bleSender.py] : [getBluetoothServices] : Couldn't find the RaspberryPi Bluetooth service : Invalid uuid
Traceback (most recent call last):
  File "bleSender.py", line 53, in getBluetoothServices
    bleService = find_service( uuid = self.uuid, address = self.addr )
  File "/usr/lib/python2.7/dist-packages/bluetooth/bluez.py", line 199, in find_service
    s.connect (addr)
KeyboardInterrupt
[2019-10-30 14:24:58,936] : [ERROR] : [bleClientLogger] : [bleSender.py] : [getBluetoothConnection] : Failed to connect to BLAH BLAH
[2019-10-30 14:24:58,942] : [ERROR] : [bleClientLogger] : [bleSender.py] : [sendData] : Failed to send data over bluetooth connection
Traceback (most recent call last):
  File "bleSender.py", line 120, in sendData
    self.clientSocket.send(_serializedData)
  File "<string>", line 5, in send
BluetoothError: (107, 'Transport endpoint is not connected')
[2019-10-30 14:31:19,825] : [ERROR] : [bleClientLogger] : [bleSender.py] : [getBluetoothServices] : Couldn't find the RaspberryPi Bluetooth service : Invalid uuid
Traceback (most recent call last):
  File "bleSender.py", line 64, in getBluetoothServices
    raise SystemExit(), None
SystemExit
[2019-10-30 14:31:19,830] : [ERROR] : [bleClientLogger] : [bleSender.py] : [getBluetoothConnection] : Failed to connect to BLAH BLAH
[2019-10-30 14:31:19,836] : [ERROR] : [bleClientLogger] : [bleSender.py] : [sendData] : Failed to send data over bluetooth connection
Traceback (most recent call last):
  File "bleSender.py", line 120, in sendData
    self.clientSocket.send(_serializedData)
  File "<string>", line 5, in send
BluetoothError: (107, 'Transport endpoint is not connected')
[2019-10-30 15:16:43,057] : [ERROR] : [bleClientLogger] : [bleSender.py] : [getBluetoothServices] : Couldn't find the RaspberryPi Bluetooth service : Invalid uuid
Traceback (most recent call last):
  File "bleSender.py", line 64, in getBluetoothServices
    raise SystemExit(), None
SystemExit
[2019-10-30 15:16:43,061] : [ERROR] : [bleClientLogger] : [bleSender.py] : [getBluetoothConnection] : Failed to connect to BLAH BLAH
[2019-10-30 15:16:43,066] : [ERROR] : [bleClientLogger] : [bleSender.py] : [sendData] : Failed to send data over bluetooth connection
Traceback (most recent call last):
  File "bleSender.py", line 120, in sendData
    self.clientSocket.send(_serializedData)
  File "<string>", line 5, in send
BluetoothError: (107, 'Transport endpoint is not connected')
[2019-10-30 15:19:54,971] : [ERROR] : [bleClientLogger] : [bleSender.py] : [getBluetoothServices] : Couldn't find the RaspberryPi Bluetooth service : Invalid uuid
Traceback (most recent call last):
  File "bleSender.py", line 64, in getBluetoothServices
    raise SystemExit(), None
SystemExit
[2019-10-30 15:19:54,979] : [ERROR] : [bleClientLogger] : [bleSender.py] : [getBluetoothConnection] : Failed to connect to BLAH BLAH
[2019-10-30 15:19:54,985] : [ERROR] : [bleClientLogger] : [bleSender.py] : [sendData] : Failed to send data over bluetooth connection
Traceback (most recent call last):
  File "bleSender.py", line 120, in sendData
    self.clientSocket.send(_serializedData)
  File "<string>", line 5, in send
BluetoothError: (107, 'Transport endpoint is not connected')
[2019-10-30 17:57:43,273] : [ERROR] : [bleServerLogger] : [bleReceiver.py] : [acceptBluetoothConnection] : Failed to accept bluetooth connection ... 
Traceback (most recent call last):
  File "bleReceiver.py", line 92, in acceptBluetoothConnection
    self.clientSocket, clientInfo = self.serverSocket.accept()
  File "/usr/lib/python2.7/dist-packages/bluetooth/bluez.py", line 129, in accept
    client, addr = self._sock.accept ()
KeyboardInterrupt
[2019-10-30 17:57:43,277] : [ERROR] : [bleServerLogger] : [bleReceiver.py] : [deserializedData] : Failed to de-serialized string ... 
Traceback (most recent call last):
  File "bleReceiver.py", line 119, in deserializedData
    self.dataObj=pickle.loads(_dataRecv)
TypeError: loads() argument 1 must be string, not None
[2019-10-30 17:57:43,282] : [ERROR] : [bleServerLogger] : [bleReceiver.py] : [closeBluetoothSocket] : Failed to close the bluetooth sockets 
Traceback (most recent call last):
  File "bleReceiver.py", line 141, in closeBluetoothSocket
    self.clientSocket.close()
AttributeError: 'NoneType' object has no attribute 'close'
[2019-10-30 18:13:43,771] : [ERROR] : [bleServerLogger] : [bleReceiver.py] : [acceptBluetoothConnection] : Failed to accept bluetooth connection ... 
Traceback (most recent call last):
  File "bleReceiver.py", line 92, in acceptBluetoothConnection
    self.clientSocket, clientInfo = self.serverSocket.accept()
  File "/usr/lib/python2.7/dist-packages/bluetooth/bluez.py", line 129, in accept
    client, addr = self._sock.accept ()
KeyboardInterrupt
[2019-10-30 18:13:43,773] : [ERROR] : [bleServerLogger] : [bleReceiver.py] : [deserializedData] : Failed to de-serialized string ... 
Traceback (most recent call last):
  File "bleReceiver.py", line 119, in deserializedData
    self.dataObj=pickle.loads(_dataRecv)
TypeError: loads() argument 1 must be string, not None
[2019-10-30 18:13:43,774] : [ERROR] : [bleServerLogger] : [bleReceiver.py] : [closeBluetoothSocket] : Failed to close the bluetooth sockets 
Traceback (most recent call last):
  File "bleReceiver.py", line 141, in closeBluetoothSocket
    self.clientSocket.close()
AttributeError: 'NoneType' object has no attribute 'close'
[2019-10-30 18:15:54,768] : [ERROR] : [bleServerLogger] : [bleReceiver.py] : [acceptBluetoothConnection] : Failed to accept bluetooth connection ... 
Traceback (most recent call last):
  File "bleReceiver.py", line 92, in acceptBluetoothConnection
    self.clientSocket, clientInfo = self.serverSocket.accept()
  File "/usr/lib/python2.7/dist-packages/bluetooth/bluez.py", line 129, in accept
    client, addr = self._sock.accept ()
KeyboardInterrupt
[2019-10-30 18:15:54,771] : [ERROR] : [bleServerLogger] : [bleReceiver.py] : [deserializedData] : Failed to de-serialized string ... 
Traceback (most recent call last):
  File "bleReceiver.py", line 119, in deserializedData
    self.dataObj=pickle.loads(_dataRecv)
TypeError: loads() argument 1 must be string, not None
[2019-10-30 18:15:54,775] : [ERROR] : [bleServerLogger] : [bleReceiver.py] : [closeBluetoothSocket] : Failed to close the bluetooth sockets 
Traceback (most recent call last):
  File "bleReceiver.py", line 141, in closeBluetoothSocket
    self.clientSocket.close()
AttributeError: 'NoneType' object has no attribute 'close'
[2019-10-30 18:17:34,782] : [ERROR] : [bleServerLogger] : [bleReceiver.py] : [acceptBluetoothConnection] : Failed to accept bluetooth connection ... 
Traceback (most recent call last):
  File "bleReceiver.py", line 92, in acceptBluetoothConnection
    self.clientSocket, clientInfo = self.serverSocket.accept()
  File "/usr/lib/python2.7/dist-packages/bluetooth/bluez.py", line 129, in accept
    client, addr = self._sock.accept ()
KeyboardInterrupt
[2019-10-30 18:17:34,786] : [ERROR] : [bleServerLogger] : [bleReceiver.py] : [deserializedData] : Failed to de-serialized string ... 
Traceback (most recent call last):
  File "bleReceiver.py", line 119, in deserializedData
    self.dataObj=pickle.loads(_dataRecv)
TypeError: loads() argument 1 must be string, not None
[2019-10-30 18:17:34,790] : [ERROR] : [bleServerLogger] : [bleReceiver.py] : [closeBluetoothSocket] : Failed to close the bluetooth sockets 
Traceback (most recent call last):
  File "bleReceiver.py", line 141, in closeBluetoothSocket
    self.clientSocket.close()
AttributeError: 'NoneType' object has no attribute 'close'
[2019-10-30 18:19:27,348] : [ERROR] : [bleServerLogger] : [bleReceiver.py] : [acceptBluetoothConnection] : Failed to accept bluetooth connection ... 
Traceback (most recent call last):
  File "bleReceiver.py", line 92, in acceptBluetoothConnection
    self.clientSocket, clientInfo = self.serverSocket.accept()
  File "/usr/lib/python2.7/dist-packages/bluetooth/bluez.py", line 129, in accept
    client, addr = self._sock.accept ()
KeyboardInterrupt
[2019-10-30 18:19:27,352] : [ERROR] : [bleServerLogger] : [bleReceiver.py] : [deserializedData] : Failed to de-serialized string ... 
Traceback (most recent call last):
  File "bleReceiver.py", line 119, in deserializedData
    self.dataObj=pickle.loads(_dataRecv)
TypeError: loads() argument 1 must be string, not None
[2019-10-30 18:19:27,355] : [ERROR] : [bleServerLogger] : [bleReceiver.py] : [closeBluetoothSocket] : Failed to close the bluetooth sockets 
Traceback (most recent call last):
  File "bleReceiver.py", line 141, in closeBluetoothSocket
    self.clientSocket.close()
AttributeError: 'NoneType' object has no attribute 'close'
[2019-10-30 18:19:44,063] : [ERROR] : [bleClientLogger] : [bleSender.py] : [getBluetoothServices] : Couldn't find the RaspberryPi Bluetooth service : Invalid uuid
Traceback (most recent call last):
  File "bleSender.py", line 53, in getBluetoothServices
    bleService = find_service( name = "PI", uuid = self.uuid, address = self.addr )
  File "/usr/lib/python2.7/dist-packages/bluetooth/bluez.py", line 186, in find_service
    devices = discover_devices ()
  File "/usr/lib/python2.7/dist-packages/bluetooth/bluez.py", line 22, in discover_devices
    raise BluetoothError ("error communicating with local "
BluetoothError: error communicating with local bluetooth adapter
[2019-10-30 18:19:44,064] : [ERROR] : [bleClientLogger] : [bleSender.py] : [getBluetoothConnection] : Failed to connect to BLAH BLAH
[2019-10-30 18:19:44,065] : [ERROR] : [bleClientLogger] : [bleSender.py] : [sendData] : Failed to send data over bluetooth connection
Traceback (most recent call last):
  File "bleSender.py", line 120, in sendData
    self.clientSocket.send(_serializedData)
  File "<string>", line 5, in send
BluetoothError: (107, 'Transport endpoint is not connected')
[2019-10-30 18:19:48,555] : [ERROR] : [bleClientLogger] : [bleSender.py] : [getBluetoothServices] : Couldn't find the RaspberryPi Bluetooth service : Invalid uuid
Traceback (most recent call last):
  File "bleSender.py", line 53, in getBluetoothServices
    bleService = find_service( name = "PI", uuid = self.uuid, address = self.addr )
  File "/usr/lib/python2.7/dist-packages/bluetooth/bluez.py", line 186, in find_service
    devices = discover_devices ()
  File "/usr/lib/python2.7/dist-packages/bluetooth/bluez.py", line 22, in discover_devices
    raise BluetoothError ("error communicating with local "
BluetoothError: error communicating with local bluetooth adapter
[2019-10-30 18:19:48,555] : [ERROR] : [bleClientLogger] : [bleSender.py] : [getBluetoothConnection] : Failed to connect to BLAH BLAH
[2019-10-30 18:19:48,556] : [ERROR] : [bleClientLogger] : [bleSender.py] : [sendData] : Failed to send data over bluetooth connection
Traceback (most recent call last):
  File "bleSender.py", line 120, in sendData
    self.clientSocket.send(_serializedData)
  File "<string>", line 5, in send
BluetoothError: (107, 'Transport endpoint is not connected')
[2019-10-30 18:19:57,189] : [ERROR] : [bleClientLogger] : [bleSender.py] : [getBluetoothServices] : Couldn't find the RaspberryPi Bluetooth service : Invalid uuid
Traceback (most recent call last):
  File "bleSender.py", line 53, in getBluetoothServices
    bleService = find_service( name = "PI", uuid = self.uuid, address = self.addr )
  File "/usr/lib/python2.7/dist-packages/bluetooth/bluez.py", line 186, in find_service
    devices = discover_devices ()
  File "/usr/lib/python2.7/dist-packages/bluetooth/bluez.py", line 22, in discover_devices
    raise BluetoothError ("error communicating with local "
BluetoothError: error communicating with local bluetooth adapter
[2019-10-30 18:19:57,190] : [ERROR] : [bleClientLogger] : [bleSender.py] : [getBluetoothConnection] : Failed to connect to BLAH BLAH
[2019-10-30 18:19:57,191] : [ERROR] : [bleClientLogger] : [bleSender.py] : [sendData] : Failed to send data over bluetooth connection
Traceback (most recent call last):
  File "bleSender.py", line 120, in sendData
    self.clientSocket.send(_serializedData)
  File "<string>", line 5, in send
BluetoothError: (107, 'Transport endpoint is not connected')
[2019-10-30 18:21:58,430] : [ERROR] : [bleClientLogger] : [bleSender.py] : [getBluetoothServices] : Couldn't find the RaspberryPi Bluetooth service : Invalid uuid
Traceback (most recent call last):
  File "bleSender.py", line 54, in getBluetoothServices
    bleService = find_service( uuid = self.uuid, address = self.addr )
  File "/usr/lib/python2.7/dist-packages/bluetooth/bluez.py", line 186, in find_service
    devices = discover_devices ()
  File "/usr/lib/python2.7/dist-packages/bluetooth/bluez.py", line 22, in discover_devices
    raise BluetoothError ("error communicating with local "
BluetoothError: error communicating with local bluetooth adapter
[2019-10-30 18:21:58,431] : [ERROR] : [bleClientLogger] : [bleSender.py] : [getBluetoothConnection] : Failed to connect to BLAH BLAH
[2019-10-30 18:21:58,432] : [ERROR] : [bleClientLogger] : [bleSender.py] : [sendData] : Failed to send data over bluetooth connection
Traceback (most recent call last):
  File "bleSender.py", line 121, in sendData
    self.clientSocket.send(_serializedData)
  File "<string>", line 5, in send
BluetoothError: (107, 'Transport endpoint is not connected')
[2019-10-30 18:25:08,831] : [ERROR] : [bleClientLogger] : [bleSender.py] : [getBluetoothServices] : Couldn't find the RaspberryPi Bluetooth service : Invalid uuid
Traceback (most recent call last):
  File "bleSender.py", line 54, in getBluetoothServices
    bleService = find_service( uuid = self.uuid, address = self.addr )
  File "/usr/lib/python2.7/dist-packages/bluetooth/bluez.py", line 186, in find_service
    devices = discover_devices ()
  File "/usr/lib/python2.7/dist-packages/bluetooth/bluez.py", line 19, in discover_devices
    results = _bt.hci_inquiry (sock, duration=duration, flush_cache=True)
KeyboardInterrupt
[2019-10-30 18:25:08,833] : [ERROR] : [bleClientLogger] : [bleSender.py] : [getBluetoothConnection] : Failed to connect to BLAH BLAH
[2019-10-30 18:25:08,836] : [ERROR] : [bleClientLogger] : [bleSender.py] : [sendData] : Failed to send data over bluetooth connection
Traceback (most recent call last):
  File "bleSender.py", line 121, in sendData
    self.clientSocket.send(_serializedData)
  File "<string>", line 5, in send
BluetoothError: (107, 'Transport endpoint is not connected')
[2019-10-30 18:26:45,445] : [ERROR] : [bleClientLogger] : [bleSender.py] : [getBluetoothServices] : Couldn't find the RaspberryPi Bluetooth service : Invalid uuid
Traceback (most recent call last):
  File "bleSender.py", line 54, in getBluetoothServices
    bleService = find_service( uuid = self.uuid, address = self.addr )
  File "/usr/lib/python2.7/dist-packages/bluetooth/bluez.py", line 186, in find_service
    devices = discover_devices ()
  File "/usr/lib/python2.7/dist-packages/bluetooth/bluez.py", line 19, in discover_devices
    results = _bt.hci_inquiry (sock, duration=duration, flush_cache=True)
KeyboardInterrupt
[2019-10-30 18:26:45,450] : [ERROR] : [bleClientLogger] : [bleSender.py] : [getBluetoothConnection] : Failed to connect to BLAH BLAH
[2019-10-30 18:26:45,453] : [ERROR] : [bleClientLogger] : [bleSender.py] : [sendData] : Failed to send data over bluetooth connection
Traceback (most recent call last):
  File "bleSender.py", line 121, in sendData
    self.clientSocket.send(_serializedData)
  File "<string>", line 5, in send
BluetoothError: (107, 'Transport endpoint is not connected')
[2019-11-04 20:15:22,206] : [ERROR] : [bleServerLogger] : [bleReceiver.py] : [acceptBluetoothConnection] : Failed to accept bluetooth connection ... 
Traceback (most recent call last):
  File "bleReceiver.py", line 92, in acceptBluetoothConnection
    self.clientSocket, clientInfo = self.serverSocket.accept()
  File "/usr/lib/python2.7/dist-packages/bluetooth/bluez.py", line 129, in accept
    client, addr = self._sock.accept ()
KeyboardInterrupt
[2019-11-04 20:15:22,212] : [ERROR] : [bleServerLogger] : [bleReceiver.py] : [deserializedData] : Failed to de-serialized string ... 
Traceback (most recent call last):
  File "bleReceiver.py", line 119, in deserializedData
    self.dataObj=pickle.loads(_dataRecv)
TypeError: loads() argument 1 must be string, not None
[2019-11-04 20:15:22,217] : [ERROR] : [bleServerLogger] : [bleReceiver.py] : [closeBluetoothSocket] : Failed to close the bluetooth sockets 
Traceback (most recent call last):
  File "bleReceiver.py", line 141, in closeBluetoothSocket
    self.clientSocket.close()
AttributeError: 'NoneType' object has no attribute 'close'
[2019-11-04 20:15:55,860] : [ERROR] : [bleServerLogger] : [bleReceiver.py] : [acceptBluetoothConnection] : Failed to accept bluetooth connection ... 
Traceback (most recent call last):
  File "bleReceiver.py", line 92, in acceptBluetoothConnection
    self.clientSocket, clientInfo = self.serverSocket.accept()
  File "/usr/lib/python2.7/dist-packages/bluetooth/bluez.py", line 129, in accept
    client, addr = self._sock.accept ()
KeyboardInterrupt
[2019-11-04 20:15:55,864] : [ERROR] : [bleServerLogger] : [bleReceiver.py] : [deserializedData] : Failed to de-serialized string ... 
Traceback (most recent call last):
  File "bleReceiver.py", line 119, in deserializedData
    self.dataObj=pickle.loads(_dataRecv)
TypeError: loads() argument 1 must be string, not None
[2019-11-04 20:15:55,869] : [ERROR] : [bleServerLogger] : [bleReceiver.py] : [closeBluetoothSocket] : Failed to close the bluetooth sockets 
Traceback (most recent call last):
  File "bleReceiver.py", line 141, in closeBluetoothSocket
    self.clientSocket.close()
AttributeError: 'NoneType' object has no attribute 'close'
[2019-11-04 20:16:49,881] : [ERROR] : [bleServerLogger] : [bleReceiver.py] : [deserializedData] : Failed to de-serialized string ... 
Traceback (most recent call last):
  File "bleReceiver.py", line 119, in deserializedData
    self.dataObj=pickle.loads(_dataRecv)
TypeError: loads() argument 1 must be string, not None
[2019-11-05 01:06:36,852] : [ERROR] : [bleClientLogger] : [newSender.py] : [sendData] : Failed to send data over bluetooth connection
Traceback (most recent call last):
  File "newSender.py", line 164, in sendData
    dataRecv= self.clientSocket.recv(1024)
  File "<string>", line 5, in recv
BluetoothError: (104, 'Connection reset by peer')
[2019-11-05 01:12:35,308] : [ERROR] : [bleClientLogger] : [newSender.py] : [sendData] : Failed to send data over bluetooth connection
Traceback (most recent call last):
  File "newSender.py", line 121, in sendData
    dataRecv= self.clientSocket.recv(1024)
  File "<string>", line 5, in recv
BluetoothError: (104, 'Connection reset by peer')
[2019-11-05 11:52:07,464] : [ERROR] : [bleClientLogger] : [newSender.py] : [sendData] : Failed to send data over bluetooth connection
Traceback (most recent call last):
  File "newSender.py", line 121, in sendData
    dataRecv= self.clientSocket.recv(1024)
  File "<string>", line 5, in recv
BluetoothError: (104, 'Connection reset by peer')
[2019-11-05 13:49:03,707] : [ERROR] : [bleClientLogger] : [newSender.py] : [sendData] : Failed to send data over bluetooth connection
Traceback (most recent call last):
  File "newSender.py", line 122, in sendData
    dataRecv= self.clientSocket.recv(1024)
  File "<string>", line 5, in recv
BluetoothError: (104, 'Connection reset by peer')
[2019-11-05 13:52:18,100] : [ERROR] : [bleClientLogger] : [newSender.py] : [sendData] : Failed to send data over bluetooth connection
Traceback (most recent call last):
  File "newSender.py", line 122, in sendData
    dataRecv= self.clientSocket.recv(1024)
  File "<string>", line 5, in recv
BluetoothError: (104, 'Connection reset by peer')
[2019-11-05 13:53:19,798] : [ERROR] : [bleClientLogger] : [newSender.py] : [sendData] : Failed to send data over bluetooth connection
Traceback (most recent call last):
  File "newSender.py", line 123, in sendData
    dataRecv= self.clientSocket.recv(1024)
  File "<string>", line 5, in recv
BluetoothError: (104, 'Connection reset by peer')
[2019-11-05 14:03:07,345] : [ERROR] : [bleClientLogger] : [newSender.py] : [sendData] : Failed to send data over bluetooth connection
Traceback (most recent call last):
  File "newSender.py", line 123, in sendData
    dataRecv= self.clientSocket.recv(1024)
  File "<string>", line 5, in recv
BluetoothError: (104, 'Connection reset by peer')
[2019-11-05 14:10:54,587] : [ERROR] : [bleClientLogger] : [newSender.py] : [sendData] : Failed to send data over bluetooth connection
Traceback (most recent call last):
  File "newSender.py", line 123, in sendData
    dataRecv= self.clientSocket.recv(1024)
  File "<string>", line 5, in recv
BluetoothError: (104, 'Connection reset by peer')
[2019-11-05 14:15:59,161] : [ERROR] : [bleClientLogger] : [newSender.py] : [sendData] : Failed to send data over bluetooth connection
Traceback (most recent call last):
  File "newSender.py", line 123, in sendData
    dataRecv= self.clientSocket.recv(1024)
  File "<string>", line 5, in recv
BluetoothError: (104, 'Connection reset by peer')
[2019-11-05 14:22:35,317] : [ERROR] : [bleClientLogger] : [newSender.py] : [sendData] : Failed to send data over bluetooth connection
Traceback (most recent call last):
  File "newSender.py", line 123, in sendData
    dataRecv= self.clientSocket.recv(1024)
  File "<string>", line 5, in recv
BluetoothError: (104, 'Connection reset by peer')
[2019-11-05 14:22:55,355] : [ERROR] : [bleClientLogger] : [newSender.py] : [sendData] : Failed to send data over bluetooth connection
Traceback (most recent call last):
  File "newSender.py", line 123, in sendData
    dataRecv= self.clientSocket.recv(1024)
  File "<string>", line 5, in recv
BluetoothError: (104, 'Connection reset by peer')
[2019-11-05 14:39:41,487] : [ERROR] : [bleClientLogger] : [newSender.py] : [sendData] : Failed to send data over bluetooth connection
Traceback (most recent call last):
  File "newSender.py", line 123, in sendData
    dataRecv= self.clientSocket.recv(1024)
  File "<string>", line 5, in recv
BluetoothError: (104, 'Connection reset by peer')
[2019-11-05 14:58:49,472] : [ERROR] : [bleClientLogger] : [newSender.py] : [sendData] : Failed to send data over bluetooth connection
Traceback (most recent call last):
  File "newSender.py", line 123, in sendData
    dataRecv= self.clientSocket.recv(1024)
  File "<string>", line 5, in recv
BluetoothError: (104, 'Connection reset by peer')
[2019-11-05 15:02:03,097] : [ERROR] : [bleClientLogger] : [newSender.py] : [sendData] : Failed to send data over bluetooth connection
Traceback (most recent call last):
  File "newSender.py", line 123, in sendData
    dataRecv= self.clientSocket.recv(1024)
  File "<string>", line 5, in recv
BluetoothError: (104, 'Connection reset by peer')
[2019-11-05 15:04:46,304] : [ERROR] : [bleClientLogger] : [newSender.py] : [sendData] : Failed to send data over bluetooth connection
Traceback (most recent call last):
  File "newSender.py", line 123, in sendData
    dataRecv= self.clientSocket.recv(1024)
  File "<string>", line 5, in recv
BluetoothError: (104, 'Connection reset by peer')
[2019-11-05 15:05:11,933] : [ERROR] : [bleClientLogger] : [newSender.py] : [sendData] : Failed to send data over bluetooth connection
Traceback (most recent call last):
  File "newSender.py", line 123, in sendData
    dataRecv= self.clientSocket.recv(1024)
  File "<string>", line 5, in recv
BluetoothError: (104, 'Connection reset by peer')
[2019-11-12 13:10:35,505] : [ERROR] : [bleClientLogger] : [newSender.py] : [sendData] : Failed to send data over bluetooth connection
Traceback (most recent call last):
  File "newSender.py", line 123, in sendData
    dataRecv= self.clientSocket.recv(1024)
  File "<string>", line 5, in recv
BluetoothError: (104, 'Connection reset by peer')
[2019-11-12 13:51:36,612] : [ERROR] : [bleClientLogger] : [newSender.py] : [sendData] : Failed to send data over bluetooth connection
Traceback (most recent call last):
  File "newSender.py", line 123, in sendData
    dataRecv= self.clientSocket.recv(1024)
  File "<string>", line 5, in recv
BluetoothError: (104, 'Connection reset by peer')
[2019-11-12 14:21:00,883] : [ERROR] : [bleClientLogger] : [newSender.py] : [sendData] : Failed to send data over bluetooth connection
Traceback (most recent call last):
  File "newSender.py", line 123, in sendData
    dataRecv= self.clientSocket.recv(1024)
  File "<string>", line 5, in recv
BluetoothError: (104, 'Connection reset by peer')
[2019-11-12 14:23:52,741] : [ERROR] : [bleClientLogger] : [newSender.py] : [sendData] : Failed to send data over bluetooth connection
Traceback (most recent call last):
  File "newSender.py", line 123, in sendData
    dataRecv= self.clientSocket.recv(1024)
  File "<string>", line 5, in recv
BluetoothError: (104, 'Connection reset by peer')
[2019-11-12 14:29:27,827] : [ERROR] : [bleClientLogger] : [newSender.py] : [sendData] : Failed to send data over bluetooth connection
Traceback (most recent call last):
  File "newSender.py", line 123, in sendData
    dataRecv= self.clientSocket.recv(1024)
  File "<string>", line 5, in recv
BluetoothError: (104, 'Connection reset by peer')
[2019-11-12 14:42:05,099] : [ERROR] : [bleClientLogger] : [newSender.py] : [sendData] : Failed to send data over bluetooth connection
Traceback (most recent call last):
  File "newSender.py", line 123, in sendData
    dataRecv= self.clientSocket.recv(1024)
  File "<string>", line 5, in recv
BluetoothError: (104, 'Connection reset by peer')
[2019-11-12 14:42:37,372] : [ERROR] : [bleClientLogger] : [newSender.py] : [sendData] : Failed to send data over bluetooth connection
Traceback (most recent call last):
  File "newSender.py", line 123, in sendData
    dataRecv= self.clientSocket.recv(1024)
  File "<string>", line 5, in recv
BluetoothError: (104, 'Connection reset by peer')
[2019-11-12 15:22:19,137] : [ERROR] : [bleClientLogger] : [newSender.py] : [sendData] : Failed to send data over bluetooth connection
Traceback (most recent call last):
  File "newSender.py", line 123, in sendData
    dataRecv= self.clientSocket.recv(1024)
  File "<string>", line 5, in recv
BluetoothError: (104, 'Connection reset by peer')
[2019-11-12 15:22:53,555] : [ERROR] : [bleClientLogger] : [newSender.py] : [sendData] : Failed to send data over bluetooth connection
Traceback (most recent call last):
  File "newSender.py", line 123, in sendData
    dataRecv= self.clientSocket.recv(1024)
  File "<string>", line 5, in recv
BluetoothError: (104, 'Connection reset by peer')
[2019-11-12 15:27:44,730] : [ERROR] : [bleClientLogger] : [newSender.py] : [sendData] : Failed to send data over bluetooth connection
Traceback (most recent call last):
  File "newSender.py", line 123, in sendData
    dataRecv= self.clientSocket.recv(1024)
  File "<string>", line 5, in recv
BluetoothError: (104, 'Connection reset by peer')
[2019-11-13 11:15:20,069] : [ERROR] : [bleClientLogger] : [newSender.py] : [acceptBluetoothConnection] : Failed to accept bluetooth connection ... 
Traceback (most recent call last):
  File "newSender.py", line 91, in acceptBluetoothConnection
    self.clientSocket, clientInfo = self.serverSocket.accept()
  File "/usr/lib/python2.7/dist-packages/bluetooth/bluez.py", line 129, in accept
    client, addr = self._sock.accept ()
KeyboardInterrupt
[2019-11-13 11:15:20,074] : [ERROR] : [bleClientLogger] : [newSender.py] : [sendData] : Failed to send data over bluetooth connection
Traceback (most recent call last):
  File "newSender.py", line 118, in sendData
    self.clientSocket.send(_serializedData)
AttributeError: 'NoneType' object has no attribute 'send'
[2019-11-13 11:15:20,075] : [ERROR] : [bleClientLogger] : [newSender.py] : [closeBluetoothSocket] : Failed to close the bluetooth client socket 
Traceback (most recent call last):
  File "newSender.py", line 140, in closeBluetoothSocket
    self.clientSocket.close()
AttributeError: 'NoneType' object has no attribute 'close'
[2019-11-13 11:38:50,861] : [ERROR] : [bleClientLogger] : [newSender.py] : [acceptBluetoothConnection] : Failed to accept bluetooth connection ... 
Traceback (most recent call last):
  File "newSender.py", line 91, in acceptBluetoothConnection
    self.clientSocket, clientInfo = self.serverSocket.accept()
  File "/usr/lib/python2.7/dist-packages/bluetooth/bluez.py", line 129, in accept
    client, addr = self._sock.accept ()
KeyboardInterrupt
[2019-11-13 11:38:50,865] : [ERROR] : [bleClientLogger] : [newSender.py] : [sendData] : Failed to send data over bluetooth connection
Traceback (most recent call last):
  File "newSender.py", line 118, in sendData
    self.clientSocket.send(_serializedData)
AttributeError: 'NoneType' object has no attribute 'send'
[2019-11-13 11:38:50,866] : [ERROR] : [bleClientLogger] : [newSender.py] : [closeBluetoothSocket] : Failed to close the bluetooth client socket 
Traceback (most recent call last):
  File "newSender.py", line 140, in closeBluetoothSocket
    self.clientSocket.close()
AttributeError: 'NoneType' object has no attribute 'close'
[2019-11-13 11:40:40,960] : [ERROR] : [bleClientLogger] : [newSender.py] : [acceptBluetoothConnection] : Failed to accept bluetooth connection ... 
Traceback (most recent call last):
  File "newSender.py", line 91, in acceptBluetoothConnection
    self.clientSocket, clientInfo = self.serverSocket.accept()
  File "/usr/lib/python2.7/dist-packages/bluetooth/bluez.py", line 129, in accept
    client, addr = self._sock.accept ()
KeyboardInterrupt
[2019-11-13 11:40:40,964] : [ERROR] : [bleClientLogger] : [newSender.py] : [sendData] : Failed to send data over bluetooth connection
Traceback (most recent call last):
  File "newSender.py", line 118, in sendData
    self.clientSocket.send(_serializedData)
AttributeError: 'NoneType' object has no attribute 'send'
[2019-11-13 11:40:40,965] : [ERROR] : [bleClientLogger] : [newSender.py] : [closeBluetoothSocket] : Failed to close the bluetooth client socket 
Traceback (most recent call last):
  File "newSender.py", line 140, in closeBluetoothSocket
    self.clientSocket.close()
AttributeError: 'NoneType' object has no attribute 'close'
[2019-11-13 11:45:51,932] : [ERROR] : [bleClientLogger] : [newSender.py] : [sendData] : Failed to send data over bluetooth connection
Traceback (most recent call last):
  File "newSender.py", line 123, in sendData
    dataRecv= self.clientSocket.recv(1024)
  File "<string>", line 5, in recv
BluetoothError: (104, 'Connection reset by peer')
[2019-11-13 11:46:03,510] : [ERROR] : [bleClientLogger] : [newSender.py] : [sendData] : Failed to send data over bluetooth connection
Traceback (most recent call last):
  File "newSender.py", line 123, in sendData
    dataRecv= self.clientSocket.recv(1024)
  File "<string>", line 5, in recv
BluetoothError: (104, 'Connection reset by peer')
[2019-11-13 11:47:40,150] : [ERROR] : [bleClientLogger] : [newSender.py] : [sendData] : Failed to send data over bluetooth connection
Traceback (most recent call last):
  File "newSender.py", line 123, in sendData
    dataRecv= self.clientSocket.recv(1024)
  File "<string>", line 5, in recv
BluetoothError: (104, 'Connection reset by peer')
[2019-11-13 11:48:15,476] : [ERROR] : [bleClientLogger] : [newSender.py] : [sendData] : Failed to send data over bluetooth connection
Traceback (most recent call last):
  File "newSender.py", line 123, in sendData
    dataRecv= self.clientSocket.recv(1024)
  File "<string>", line 5, in recv
BluetoothError: (104, 'Connection reset by peer')
[2019-11-13 11:50:52,967] : [ERROR] : [bleClientLogger] : [newSender.py] : [sendData] : Failed to send data over bluetooth connection
Traceback (most recent call last):
  File "newSender.py", line 123, in sendData
    dataRecv= self.clientSocket.recv(1024)
  File "<string>", line 5, in recv
BluetoothError: (104, 'Connection reset by peer')
[2019-11-13 11:51:05,725] : [ERROR] : [bleClientLogger] : [newSender.py] : [sendData] : Failed to send data over bluetooth connection
Traceback (most recent call last):
  File "newSender.py", line 123, in sendData
    dataRecv= self.clientSocket.recv(1024)
  File "<string>", line 5, in recv
BluetoothError: (104, 'Connection reset by peer')
[2019-11-13 11:56:01,908] : [ERROR] : [bleClientLogger] : [newSender.py] : [sendData] : Failed to send data over bluetooth connection
Traceback (most recent call last):
  File "newSender.py", line 123, in sendData
    dataRecv= self.clientSocket.recv(1024)
  File "<string>", line 5, in recv
BluetoothError: (104, 'Connection reset by peer')
[2019-11-13 11:58:35,390] : [ERROR] : [bleClientLogger] : [newSender.py] : [acceptBluetoothConnection] : Failed to accept bluetooth connection ... 
Traceback (most recent call last):
  File "newSender.py", line 91, in acceptBluetoothConnection
    self.clientSocket, clientInfo = self.serverSocket.accept()
  File "/usr/lib/python2.7/dist-packages/bluetooth/bluez.py", line 129, in accept
    client, addr = self._sock.accept ()
KeyboardInterrupt
[2019-11-13 11:58:35,397] : [ERROR] : [bleClientLogger] : [newSender.py] : [sendData] : Failed to send data over bluetooth connection
Traceback (most recent call last):
  File "newSender.py", line 118, in sendData
    self.clientSocket.send(_serializedData)
AttributeError: 'NoneType' object has no attribute 'send'
[2019-11-13 11:58:35,399] : [ERROR] : [bleClientLogger] : [newSender.py] : [closeBluetoothSocket] : Failed to close the bluetooth client socket 
Traceback (most recent call last):
  File "newSender.py", line 140, in closeBluetoothSocket
    self.clientSocket.close()
AttributeError: 'NoneType' object has no attribute 'close'
[2019-11-13 11:59:38,670] : [ERROR] : [bleClientLogger] : [newSender.py] : [acceptBluetoothConnection] : Failed to accept bluetooth connection ... 
Traceback (most recent call last):
  File "newSender.py", line 91, in acceptBluetoothConnection
    self.clientSocket, clientInfo = self.serverSocket.accept()
  File "/usr/lib/python2.7/dist-packages/bluetooth/bluez.py", line 129, in accept
    client, addr = self._sock.accept ()
KeyboardInterrupt
[2019-11-13 11:59:38,676] : [ERROR] : [bleClientLogger] : [newSender.py] : [sendData] : Failed to send data over bluetooth connection
Traceback (most recent call last):
  File "newSender.py", line 118, in sendData
    self.clientSocket.send(_serializedData)
AttributeError: 'NoneType' object has no attribute 'send'
[2019-11-13 11:59:38,677] : [ERROR] : [bleClientLogger] : [newSender.py] : [closeBluetoothSocket] : Failed to close the bluetooth client socket 
Traceback (most recent call last):
  File "newSender.py", line 140, in closeBluetoothSocket
    self.clientSocket.close()
AttributeError: 'NoneType' object has no attribute 'close'
[2019-11-13 12:09:19,481] : [ERROR] : [bleClientLogger] : [newSender.py] : [acceptBluetoothConnection] : Failed to accept bluetooth connection ... 
Traceback (most recent call last):
  File "newSender.py", line 91, in acceptBluetoothConnection
    self.clientSocket, clientInfo = self.serverSocket.accept()
  File "/usr/lib/python2.7/dist-packages/bluetooth/bluez.py", line 129, in accept
    client, addr = self._sock.accept ()
KeyboardInterrupt
[2019-11-13 12:09:19,486] : [ERROR] : [bleClientLogger] : [newSender.py] : [sendData] : Failed to send data over bluetooth connection
Traceback (most recent call last):
  File "newSender.py", line 118, in sendData
    self.clientSocket.send(_serializedData)
AttributeError: 'NoneType' object has no attribute 'send'
[2019-11-13 12:09:19,488] : [ERROR] : [bleClientLogger] : [newSender.py] : [closeBluetoothSocket] : Failed to close the bluetooth client socket 
Traceback (most recent call last):
  File "newSender.py", line 140, in closeBluetoothSocket
    self.clientSocket.close()
AttributeError: 'NoneType' object has no attribute 'close'
[2019-11-13 12:09:43,287] : [ERROR] : [bleClientLogger] : [newSender.py] : [sendData] : Failed to send data over bluetooth connection
Traceback (most recent call last):
  File "newSender.py", line 123, in sendData
    dataRecv= self.clientSocket.recv(1024)
  File "<string>", line 5, in recv
BluetoothError: (104, 'Connection reset by peer')
[2019-11-13 12:11:51,168] : [ERROR] : [bleClientLogger] : [newSender.py] : [acceptBluetoothConnection] : Failed to accept bluetooth connection ... 
Traceback (most recent call last):
  File "newSender.py", line 91, in acceptBluetoothConnection
    self.clientSocket, clientInfo = self.serverSocket.accept()
  File "/usr/lib/python2.7/dist-packages/bluetooth/bluez.py", line 129, in accept
    client, addr = self._sock.accept ()
KeyboardInterrupt
[2019-11-13 12:11:51,177] : [ERROR] : [bleClientLogger] : [newSender.py] : [sendData] : Failed to send data over bluetooth connection
Traceback (most recent call last):
  File "newSender.py", line 118, in sendData
    self.clientSocket.send(_serializedData)
AttributeError: 'NoneType' object has no attribute 'send'
[2019-11-13 12:11:51,178] : [ERROR] : [bleClientLogger] : [newSender.py] : [closeBluetoothSocket] : Failed to close the bluetooth client socket 
Traceback (most recent call last):
  File "newSender.py", line 140, in closeBluetoothSocket
    self.clientSocket.close()
AttributeError: 'NoneType' object has no attribute 'close'
[2019-11-13 12:13:11,961] : [ERROR] : [bleClientLogger] : [newSender.py] : [sendData] : Failed to send data over bluetooth connection
Traceback (most recent call last):
  File "newSender.py", line 123, in sendData
    dataRecv= self.clientSocket.recv(1024)
  File "<string>", line 5, in recv
BluetoothError: (104, 'Connection reset by peer')
[2019-11-13 12:16:33,986] : [ERROR] : [bleClientLogger] : [newSender.py] : [acceptBluetoothConnection] : Failed to accept bluetooth connection ... 
Traceback (most recent call last):
  File "newSender.py", line 91, in acceptBluetoothConnection
    self.clientSocket, clientInfo = self.serverSocket.accept()
  File "/usr/lib/python2.7/dist-packages/bluetooth/bluez.py", line 129, in accept
    client, addr = self._sock.accept ()
KeyboardInterrupt
[2019-11-13 12:16:33,993] : [ERROR] : [bleClientLogger] : [newSender.py] : [sendData] : Failed to send data over bluetooth connection
Traceback (most recent call last):
  File "newSender.py", line 118, in sendData
    self.clientSocket.send(_serializedData)
AttributeError: 'NoneType' object has no attribute 'send'
[2019-11-13 12:16:33,995] : [ERROR] : [bleClientLogger] : [newSender.py] : [closeBluetoothSocket] : Failed to close the bluetooth client socket 
Traceback (most recent call last):
  File "newSender.py", line 140, in closeBluetoothSocket
    self.clientSocket.close()
AttributeError: 'NoneType' object has no attribute 'close'
[2019-11-13 12:16:42,644] : [ERROR] : [bleClientLogger] : [newSender.py] : [sendData] : Failed to send data over bluetooth connection
Traceback (most recent call last):
  File "newSender.py", line 123, in sendData
    dataRecv= self.clientSocket.recv(1024)
  File "<string>", line 5, in recv
BluetoothError: (104, 'Connection reset by peer')
[2019-11-13 12:21:35,860] : [ERROR] : [bleClientLogger] : [newSender.py] : [acceptBluetoothConnection] : Failed to accept bluetooth connection ... 
Traceback (most recent call last):
  File "newSender.py", line 91, in acceptBluetoothConnection
    self.clientSocket, clientInfo = self.serverSocket.accept()
  File "/usr/lib/python2.7/dist-packages/bluetooth/bluez.py", line 129, in accept
    client, addr = self._sock.accept ()
KeyboardInterrupt
[2019-11-13 12:21:35,868] : [ERROR] : [bleClientLogger] : [newSender.py] : [sendData] : Failed to send data over bluetooth connection
Traceback (most recent call last):
  File "newSender.py", line 118, in sendData
    self.clientSocket.send(_serializedData)
AttributeError: 'NoneType' object has no attribute 'send'
[2019-11-13 12:21:35,870] : [ERROR] : [bleClientLogger] : [newSender.py] : [closeBluetoothSocket] : Failed to close the bluetooth client socket 
Traceback (most recent call last):
  File "newSender.py", line 140, in closeBluetoothSocket
    self.clientSocket.close()
AttributeError: 'NoneType' object has no attribute 'close'
[2019-11-13 12:24:37,642] : [ERROR] : [bleClientLogger] : [newSender.py] : [sendData] : Failed to send data over bluetooth connection
Traceback (most recent call last):
  File "newSender.py", line 123, in sendData
    dataRecv= self.clientSocket.recv(1024)
  File "<string>", line 5, in recv
BluetoothError: (104, 'Connection reset by peer')
[2019-11-13 12:25:53,679] : [ERROR] : [bleClientLogger] : [newSender.py] : [acceptBluetoothConnection] : Failed to accept bluetooth connection ... 
Traceback (most recent call last):
  File "newSender.py", line 91, in acceptBluetoothConnection
    self.clientSocket, clientInfo = self.serverSocket.accept()
  File "/usr/lib/python2.7/dist-packages/bluetooth/bluez.py", line 129, in accept
    client, addr = self._sock.accept ()
KeyboardInterrupt
[2019-11-13 12:25:53,683] : [ERROR] : [bleClientLogger] : [newSender.py] : [sendData] : Failed to send data over bluetooth connection
Traceback (most recent call last):
  File "newSender.py", line 118, in sendData
    self.clientSocket.send(_serializedData)
AttributeError: 'NoneType' object has no attribute 'send'
[2019-11-13 12:25:53,684] : [ERROR] : [bleClientLogger] : [newSender.py] : [closeBluetoothSocket] : Failed to close the bluetooth client socket 
Traceback (most recent call last):
  File "newSender.py", line 141, in closeBluetoothSocket
    self.clientSocket.close()
AttributeError: 'NoneType' object has no attribute 'close'
[2019-11-13 12:31:49,566] : [ERROR] : [bleClientLogger] : [newSender.py] : [sendData] : Failed to send data over bluetooth connection
Traceback (most recent call last):
  File "newSender.py", line 123, in sendData
    dataRecv= self.clientSocket.recv(1024)
  File "<string>", line 5, in recv
BluetoothError: (104, 'Connection reset by peer')
[2019-11-13 12:33:09,331] : [ERROR] : [bleClientLogger] : [newSender.py] : [sendData] : Failed to send data over bluetooth connection
Traceback (most recent call last):
  File "newSender.py", line 123, in sendData
    dataRecv= self.clientSocket.recv(1024)
  File "<string>", line 5, in recv
BluetoothError: (104, 'Connection reset by peer')
[2019-11-13 12:34:41,518] : [ERROR] : [bleClientLogger] : [newSender.py] : [sendData] : Failed to send data over bluetooth connection
Traceback (most recent call last):
  File "newSender.py", line 123, in sendData
    dataRecv= self.clientSocket.recv(1024)
  File "<string>", line 5, in recv
BluetoothError: (104, 'Connection reset by peer')
[2019-11-13 12:37:05,283] : [ERROR] : [bleClientLogger] : [newSender.py] : [sendData] : Failed to send data over bluetooth connection
Traceback (most recent call last):
  File "newSender.py", line 123, in sendData
    dataRecv= self.clientSocket.recv(1024)
  File "<string>", line 5, in recv
BluetoothError: (104, 'Connection reset by peer')
[2019-11-13 12:40:09,412] : [ERROR] : [bleClientLogger] : [newSender.py] : [sendData] : Failed to send data over bluetooth connection
Traceback (most recent call last):
  File "newSender.py", line 123, in sendData
    dataRecv= self.clientSocket.recv(1024)
  File "<string>", line 5, in recv
BluetoothError: (104, 'Connection reset by peer')
[2019-11-13 12:43:49,750] : [ERROR] : [bleClientLogger] : [newSender.py] : [sendData] : Failed to send data over bluetooth connection
Traceback (most recent call last):
  File "newSender.py", line 123, in sendData
    dataRecv= self.clientSocket.recv(1024)
  File "<string>", line 5, in recv
BluetoothError: (104, 'Connection reset by peer')
[2019-11-13 12:46:14,910] : [ERROR] : [bleClientLogger] : [newSender.py] : [sendData] : Failed to send data over bluetooth connection
Traceback (most recent call last):
  File "newSender.py", line 123, in sendData
    dataRecv= self.clientSocket.recv(1024)
  File "<string>", line 5, in recv
BluetoothError: (104, 'Connection reset by peer')
[2019-11-13 12:46:52,317] : [ERROR] : [bleClientLogger] : [newSender.py] : [sendData] : Failed to send data over bluetooth connection
Traceback (most recent call last):
  File "newSender.py", line 123, in sendData
    dataRecv= self.clientSocket.recv(1024)
  File "<string>", line 5, in recv
BluetoothError: (104, 'Connection reset by peer')
[2019-11-13 12:47:09,522] : [ERROR] : [bleClientLogger] : [newSender.py] : [sendData] : Failed to send data over bluetooth connection
Traceback (most recent call last):
  File "newSender.py", line 123, in sendData
    dataRecv= self.clientSocket.recv(1024)
  File "<string>", line 5, in recv
BluetoothError: (104, 'Connection reset by peer')
[2019-11-13 12:48:27,268] : [ERROR] : [bleClientLogger] : [newSender.py] : [sendData] : Failed to send data over bluetooth connection
Traceback (most recent call last):
  File "newSender.py", line 123, in sendData
    dataRecv= self.clientSocket.recv(1024)
  File "<string>", line 5, in recv
BluetoothError: (104, 'Connection reset by peer')
[2019-11-13 12:49:32,230] : [ERROR] : [bleClientLogger] : [newSender.py] : [sendData] : Failed to send data over bluetooth connection
Traceback (most recent call last):
  File "newSender.py", line 123, in sendData
    dataRecv= self.clientSocket.recv(1024)
  File "<string>", line 5, in recv
BluetoothError: (104, 'Connection reset by peer')
[2019-11-13 12:51:03,635] : [ERROR] : [bleClientLogger] : [newSender.py] : [sendData] : Failed to send data over bluetooth connection
Traceback (most recent call last):
  File "newSender.py", line 123, in sendData
    dataRecv= self.clientSocket.recv(1024)
  File "<string>", line 5, in recv
BluetoothError: (104, 'Connection reset by peer')
[2019-11-13 12:59:08,215] : [ERROR] : [bleClientLogger] : [newSender.py] : [sendData] : Failed to send data over bluetooth connection
Traceback (most recent call last):
  File "newSender.py", line 123, in sendData
    dataRecv= self.clientSocket.recv(1024)
  File "<string>", line 5, in recv
BluetoothError: (104, 'Connection reset by peer')
[2019-11-13 13:01:34,028] : [ERROR] : [bleClientLogger] : [newSender.py] : [acceptBluetoothConnection] : Failed to accept bluetooth connection ... 
Traceback (most recent call last):
  File "newSender.py", line 91, in acceptBluetoothConnection
    self.clientSocket, clientInfo = self.serverSocket.accept()
  File "/usr/lib/python2.7/dist-packages/bluetooth/bluez.py", line 129, in accept
    client, addr = self._sock.accept ()
KeyboardInterrupt
[2019-11-13 13:01:34,037] : [ERROR] : [bleClientLogger] : [newSender.py] : [sendData] : Failed to send data over bluetooth connection
Traceback (most recent call last):
  File "newSender.py", line 118, in sendData
    self.clientSocket.send(_serializedData)
AttributeError: 'NoneType' object has no attribute 'send'
[2019-11-13 13:01:34,038] : [ERROR] : [bleClientLogger] : [newSender.py] : [closeBluetoothSocket] : Failed to close the bluetooth client socket 
Traceback (most recent call last):
  File "newSender.py", line 141, in closeBluetoothSocket
    self.clientSocket.close()
AttributeError: 'NoneType' object has no attribute 'close'
[2019-11-13 13:01:46,488] : [ERROR] : [bleClientLogger] : [newSender.py] : [sendData] : Failed to send data over bluetooth connection
Traceback (most recent call last):
  File "newSender.py", line 123, in sendData
    dataRecv= self.clientSocket.recv(1024)
  File "<string>", line 5, in recv
BluetoothError: (104, 'Connection reset by peer')
[2019-11-13 13:03:54,245] : [ERROR] : [bleClientLogger] : [newSender.py] : [acceptBluetoothConnection] : Failed to accept bluetooth connection ... 
Traceback (most recent call last):
  File "newSender.py", line 91, in acceptBluetoothConnection
    self.clientSocket, clientInfo = self.serverSocket.accept()
  File "/usr/lib/python2.7/dist-packages/bluetooth/bluez.py", line 129, in accept
    client, addr = self._sock.accept ()
KeyboardInterrupt
[2019-11-13 13:03:54,250] : [ERROR] : [bleClientLogger] : [newSender.py] : [sendData] : Failed to send data over bluetooth connection
Traceback (most recent call last):
  File "newSender.py", line 118, in sendData
    self.clientSocket.send(_serializedData)
AttributeError: 'NoneType' object has no attribute 'send'
[2019-11-13 13:03:54,252] : [ERROR] : [bleClientLogger] : [newSender.py] : [closeBluetoothSocket] : Failed to close the bluetooth client socket 
Traceback (most recent call last):
  File "newSender.py", line 141, in closeBluetoothSocket
    self.clientSocket.close()
AttributeError: 'NoneType' object has no attribute 'close'
[2019-11-13 13:16:15,583] : [ERROR] : [bleClientLogger] : [newSender.py] : [sendData] : Failed to send data over bluetooth connection
Traceback (most recent call last):
  File "newSender.py", line 123, in sendData
    dataRecv= self.clientSocket.recv(1024)
  File "<string>", line 5, in recv
BluetoothError: (104, 'Connection reset by peer')
[2019-11-13 13:16:55,354] : [ERROR] : [bleClientLogger] : [newSender.py] : [sendData] : Failed to send data over bluetooth connection
Traceback (most recent call last):
  File "newSender.py", line 123, in sendData
    dataRecv= self.clientSocket.recv(1024)
  File "<string>", line 5, in recv
BluetoothError: (104, 'Connection reset by peer')
[2019-11-13 13:17:46,429] : [ERROR] : [bleClientLogger] : [newSender.py] : [acceptBluetoothConnection] : Failed to accept bluetooth connection ... 
Traceback (most recent call last):
  File "newSender.py", line 91, in acceptBluetoothConnection
    self.clientSocket, clientInfo = self.serverSocket.accept()
  File "/usr/lib/python2.7/dist-packages/bluetooth/bluez.py", line 129, in accept
    client, addr = self._sock.accept ()
KeyboardInterrupt
[2019-11-13 13:17:46,437] : [ERROR] : [bleClientLogger] : [newSender.py] : [sendData] : Failed to send data over bluetooth connection
Traceback (most recent call last):
  File "newSender.py", line 118, in sendData
    self.clientSocket.send(_serializedData)
AttributeError: 'NoneType' object has no attribute 'send'
[2019-11-13 13:17:46,438] : [ERROR] : [bleClientLogger] : [newSender.py] : [closeBluetoothSocket] : Failed to close the bluetooth client socket 
Traceback (most recent call last):
  File "newSender.py", line 141, in closeBluetoothSocket
    self.clientSocket.close()
AttributeError: 'NoneType' object has no attribute 'close'
[2019-11-13 13:17:54,304] : [ERROR] : [bleClientLogger] : [newSender.py] : [sendData] : Failed to send data over bluetooth connection
Traceback (most recent call last):
  File "newSender.py", line 123, in sendData
    dataRecv= self.clientSocket.recv(1024)
  File "<string>", line 5, in recv
BluetoothError: (104, 'Connection reset by peer')
[2019-11-13 13:28:33,236] : [ERROR] : [bleClientLogger] : [newSender.py] : [acceptBluetoothConnection] : Failed to accept bluetooth connection ... 
Traceback (most recent call last):
  File "newSender.py", line 91, in acceptBluetoothConnection
    self.clientSocket, clientInfo = self.serverSocket.accept()
  File "/usr/lib/python2.7/dist-packages/bluetooth/bluez.py", line 129, in accept
    client, addr = self._sock.accept ()
KeyboardInterrupt
[2019-11-13 13:28:33,244] : [ERROR] : [bleClientLogger] : [newSender.py] : [sendData] : Failed to send data over bluetooth connection
Traceback (most recent call last):
  File "newSender.py", line 118, in sendData
    self.clientSocket.send(_serializedData)
AttributeError: 'NoneType' object has no attribute 'send'
[2019-11-13 13:28:33,246] : [ERROR] : [bleClientLogger] : [newSender.py] : [closeBluetoothSocket] : Failed to close the bluetooth client socket 
Traceback (most recent call last):
  File "newSender.py", line 141, in closeBluetoothSocket
    self.clientSocket.close()
AttributeError: 'NoneType' object has no attribute 'close'
[2019-11-13 13:28:39,524] : [ERROR] : [bleClientLogger] : [newSender.py] : [sendData] : Failed to send data over bluetooth connection
Traceback (most recent call last):
  File "newSender.py", line 123, in sendData
    dataRecv= self.clientSocket.recv(1024)
  File "<string>", line 5, in recv
BluetoothError: (104, 'Connection reset by peer')
[2019-11-13 13:33:33,923] : [ERROR] : [bleClientLogger] : [newSender.py] : [sendData] : Failed to send data over bluetooth connection
Traceback (most recent call last):
  File "newSender.py", line 123, in sendData
    dataRecv= self.clientSocket.recv(1024)
  File "<string>", line 5, in recv
BluetoothError: (104, 'Connection reset by peer')
[2019-11-13 13:39:06,935] : [ERROR] : [bleClientLogger] : [newSender.py] : [sendData] : Failed to send data over bluetooth connection
Traceback (most recent call last):
  File "newSender.py", line 123, in sendData
    dataRecv= self.clientSocket.recv(1024)
  File "<string>", line 5, in recv
BluetoothError: (104, 'Connection reset by peer')
[2019-11-13 13:42:36,584] : [ERROR] : [bleClientLogger] : [newSender.py] : [sendData] : Failed to send data over bluetooth connection
Traceback (most recent call last):
  File "newSender.py", line 123, in sendData
    dataRecv= self.clientSocket.recv(1024)
  File "<string>", line 5, in recv
BluetoothError: (104, 'Connection reset by peer')
[2019-11-13 13:43:52,205] : [ERROR] : [bleClientLogger] : [newSender.py] : [sendData] : Failed to send data over bluetooth connection
Traceback (most recent call last):
  File "newSender.py", line 123, in sendData
    dataRecv= self.clientSocket.recv(1024)
  File "<string>", line 5, in recv
BluetoothError: (104, 'Connection reset by peer')
[2019-11-13 13:44:32,162] : [ERROR] : [bleClientLogger] : [newSender.py] : [sendData] : Failed to send data over bluetooth connection
Traceback (most recent call last):
  File "newSender.py", line 123, in sendData
    dataRecv= self.clientSocket.recv(1024)
  File "<string>", line 5, in recv
BluetoothError: (104, 'Connection reset by peer')
[2019-11-13 13:49:51,300] : [ERROR] : [bleClientLogger] : [newSender.py] : [sendData] : Failed to send data over bluetooth connection
Traceback (most recent call last):
  File "newSender.py", line 123, in sendData
    dataRecv= self.clientSocket.recv(1024)
  File "<string>", line 5, in recv
BluetoothError: (104, 'Connection reset by peer')
[2019-11-13 13:53:00,060] : [ERROR] : [bleClientLogger] : [newSender.py] : [acceptBluetoothConnection] : Failed to accept bluetooth connection ... 
Traceback (most recent call last):
  File "newSender.py", line 91, in acceptBluetoothConnection
    self.clientSocket, clientInfo = self.serverSocket.accept()
  File "/usr/lib/python2.7/dist-packages/bluetooth/bluez.py", line 129, in accept
    client, addr = self._sock.accept ()
KeyboardInterrupt
[2019-11-13 13:53:00,069] : [ERROR] : [bleClientLogger] : [newSender.py] : [sendData] : Failed to send data over bluetooth connection
Traceback (most recent call last):
  File "newSender.py", line 118, in sendData
    self.clientSocket.send(_serializedData)
AttributeError: 'NoneType' object has no attribute 'send'
[2019-11-13 13:53:00,071] : [ERROR] : [bleClientLogger] : [newSender.py] : [closeBluetoothSocket] : Failed to close the bluetooth client socket 
Traceback (most recent call last):
  File "newSender.py", line 141, in closeBluetoothSocket
    self.clientSocket.close()
AttributeError: 'NoneType' object has no attribute 'close'
[2019-11-13 13:54:11,144] : [ERROR] : [bleClientLogger] : [newSender.py] : [sendData] : Failed to send data over bluetooth connection
Traceback (most recent call last):
  File "newSender.py", line 123, in sendData
    dataRecv= self.clientSocket.recv(1024)
  File "<string>", line 5, in recv
BluetoothError: (104, 'Connection reset by peer')
[2019-11-13 13:59:38,404] : [ERROR] : [bleClientLogger] : [newSender.py] : [sendData] : Failed to send data over bluetooth connection
Traceback (most recent call last):
  File "newSender.py", line 123, in sendData
    dataRecv= self.clientSocket.recv(1024)
  File "<string>", line 5, in recv
BluetoothError: (104, 'Connection reset by peer')
[2019-11-13 14:01:43,679] : [ERROR] : [bleClientLogger] : [newSender.py] : [sendData] : Failed to send data over bluetooth connection
Traceback (most recent call last):
  File "newSender.py", line 123, in sendData
    dataRecv= self.clientSocket.recv(1024)
  File "<string>", line 5, in recv
BluetoothError: (104, 'Connection reset by peer')
[2019-11-13 14:03:46,560] : [ERROR] : [bleClientLogger] : [newSender.py] : [sendData] : Failed to send data over bluetooth connection
Traceback (most recent call last):
  File "newSender.py", line 123, in sendData
    dataRecv= self.clientSocket.recv(1024)
  File "<string>", line 5, in recv
BluetoothError: (104, 'Connection reset by peer')
[2019-11-13 14:05:11,729] : [ERROR] : [bleClientLogger] : [newSender.py] : [sendData] : Failed to send data over bluetooth connection
Traceback (most recent call last):
  File "newSender.py", line 123, in sendData
    dataRecv= self.clientSocket.recv(1024)
  File "<string>", line 5, in recv
BluetoothError: (104, 'Connection reset by peer')
[2019-11-13 14:10:12,961] : [ERROR] : [bleClientLogger] : [newSender.py] : [sendData] : Failed to send data over bluetooth connection
Traceback (most recent call last):
  File "newSender.py", line 123, in sendData
    dataRecv= self.clientSocket.recv(1024)
  File "<string>", line 5, in recv
BluetoothError: (104, 'Connection reset by peer')
[2019-11-13 14:10:55,250] : [ERROR] : [bleClientLogger] : [newSender.py] : [sendData] : Failed to send data over bluetooth connection
Traceback (most recent call last):
  File "newSender.py", line 123, in sendData
    dataRecv= self.clientSocket.recv(1024)
  File "<string>", line 5, in recv
BluetoothError: (104, 'Connection reset by peer')
[2019-11-13 14:13:16,644] : [ERROR] : [bleClientLogger] : [newSender.py] : [sendData] : Failed to send data over bluetooth connection
Traceback (most recent call last):
  File "newSender.py", line 123, in sendData
    dataRecv= self.clientSocket.recv(1024)
  File "<string>", line 5, in recv
BluetoothError: (104, 'Connection reset by peer')
[2019-11-13 14:15:12,843] : [ERROR] : [bleClientLogger] : [newSender.py] : [sendData] : Failed to send data over bluetooth connection
Traceback (most recent call last):
  File "newSender.py", line 123, in sendData
    dataRecv= self.clientSocket.recv(1024)
  File "<string>", line 5, in recv
BluetoothError: (104, 'Connection reset by peer')
[2019-11-13 14:16:48,129] : [ERROR] : [bleClientLogger] : [newSender.py] : [serializeData] : Failed to convert json object  to serialized string
Traceback (most recent call last):
  File "newSender.py", line 108, in serializeData
    serializedData = pickle.dumps(self.jsonObj, "prot2")
TypeError: an integer is required
[2019-11-13 14:16:48,130] : [ERROR] : [bleClientLogger] : [newSender.py] : [sendData] : Failed to send data over bluetooth connection
Traceback (most recent call last):
  File "newSender.py", line 117, in sendData
    _serializedData =str(len(_serializedData))+ ":"+_serializedData
TypeError: object of type 'NoneType' has no len()
[2019-11-13 14:19:20,074] : [ERROR] : [bleClientLogger] : [newSender.py] : [sendData] : Failed to send data over bluetooth connection
Traceback (most recent call last):
  File "newSender.py", line 123, in sendData
    dataRecv= self.clientSocket.recv(1024)
  File "<string>", line 5, in recv
BluetoothError: (104, 'Connection reset by peer')
[2019-11-13 14:20:51,963] : [ERROR] : [bleClientLogger] : [newSender.py] : [sendData] : Failed to send data over bluetooth connection
Traceback (most recent call last):
  File "newSender.py", line 123, in sendData
    dataRecv= self.clientSocket.recv(1024)
  File "<string>", line 5, in recv
BluetoothError: (104, 'Connection reset by peer')
[2019-11-13 14:21:56,334] : [ERROR] : [bleClientLogger] : [newSender.py] : [sendData] : Failed to send data over bluetooth connection
Traceback (most recent call last):
  File "newSender.py", line 123, in sendData
    dataRecv= self.clientSocket.recv(1024)
  File "<string>", line 5, in recv
BluetoothError: (104, 'Connection reset by peer')
[2019-11-13 14:23:21,477] : [ERROR] : [bleClientLogger] : [newSender.py] : [sendData] : Failed to send data over bluetooth connection
Traceback (most recent call last):
  File "newSender.py", line 123, in sendData
    dataRecv= self.clientSocket.recv(1024)
  File "<string>", line 5, in recv
BluetoothError: (104, 'Connection reset by peer')
[2019-11-13 14:27:11,668] : [ERROR] : [bleClientLogger] : [newSender.py] : [sendData] : Failed to send data over bluetooth connection
Traceback (most recent call last):
  File "newSender.py", line 123, in sendData
    dataRecv= self.clientSocket.recv(1024)
  File "<string>", line 5, in recv
BluetoothError: (104, 'Connection reset by peer')
[2019-11-13 14:28:23,880] : [ERROR] : [bleClientLogger] : [newSender.py] : [sendData] : Failed to send data over bluetooth connection
Traceback (most recent call last):
  File "newSender.py", line 123, in sendData
    dataRecv= self.clientSocket.recv(1024)
  File "<string>", line 5, in recv
BluetoothError: (104, 'Connection reset by peer')
[2019-11-13 14:28:55,991] : [ERROR] : [bleClientLogger] : [newSender.py] : [sendData] : Failed to send data over bluetooth connection
Traceback (most recent call last):
  File "newSender.py", line 123, in sendData
    dataRecv= self.clientSocket.recv(1024)
  File "<string>", line 5, in recv
BluetoothError: (104, 'Connection reset by peer')
[2019-11-13 14:30:05,111] : [ERROR] : [bleClientLogger] : [newSender.py] : [sendData] : Failed to send data over bluetooth connection
Traceback (most recent call last):
  File "newSender.py", line 123, in sendData
    dataRecv= self.clientSocket.recv(1024)
  File "<string>", line 5, in recv
BluetoothError: (104, 'Connection reset by peer')
[2019-11-13 14:32:14,780] : [ERROR] : [bleClientLogger] : [newSender.py] : [sendData] : Failed to send data over bluetooth connection
Traceback (most recent call last):
  File "newSender.py", line 123, in sendData
    dataRecv= self.clientSocket.recv(1024)
  File "<string>", line 5, in recv
BluetoothError: (104, 'Connection reset by peer')
[2019-11-13 14:33:49,534] : [ERROR] : [bleClientLogger] : [newSender.py] : [sendData] : Failed to send data over bluetooth connection
Traceback (most recent call last):
  File "newSender.py", line 123, in sendData
    dataRecv= self.clientSocket.recv(1024)
  File "<string>", line 5, in recv
BluetoothError: (104, 'Connection reset by peer')
[2019-11-13 14:38:04,766] : [ERROR] : [bleClientLogger] : [newSender.py] : [sendData] : Failed to send data over bluetooth connection
Traceback (most recent call last):
  File "newSender.py", line 123, in sendData
    dataRecv= self.clientSocket.recv(1024)
  File "<string>", line 5, in recv
BluetoothError: (104, 'Connection reset by peer')
[2019-11-13 14:43:55,234] : [ERROR] : [bleClientLogger] : [newSender.py] : [sendData] : Failed to send data over bluetooth connection
Traceback (most recent call last):
  File "newSender.py", line 123, in sendData
    logger.info("Sending data over bluetooth connection 3")
  File "<string>", line 5, in recv
BluetoothError: (104, 'Connection reset by peer')
[2019-11-13 14:46:42,166] : [ERROR] : [bleClientLogger] : [newSender.py] : [readJsonFile] : Failed to load content from the text.json
Traceback (most recent call last):
  File "newSender.py", line 100, in readJsonFile
    self.jsonObj = json.load(jsonFileObj)
  File "/usr/lib/python2.7/json/__init__.py", line 291, in load
    **kw)
  File "/usr/lib/python2.7/json/__init__.py", line 339, in loads
    return _default_decoder.decode(s)
  File "/usr/lib/python2.7/json/decoder.py", line 364, in decode
    obj, end = self.raw_decode(s, idx=_w(s, 0).end())
  File "/usr/lib/python2.7/json/decoder.py", line 382, in raw_decode
    raise ValueError("No JSON object could be decoded")
ValueError: No JSON object could be decoded
[2019-11-13 14:46:42,723] : [ERROR] : [bleClientLogger] : [newSender.py] : [sendData] : Failed to send data over bluetooth connection
Traceback (most recent call last):
  File "newSender.py", line 124, in sendData
    dataRecv= self.clientSocket.recv(1024)
  File "<string>", line 5, in recv
BluetoothError: (104, 'Connection reset by peer')
[2019-11-13 14:47:21,920] : [ERROR] : [bleClientLogger] : [newSender.py] : [acceptBluetoothConnection] : Failed to accept bluetooth connection ... 
Traceback (most recent call last):
  File "newSender.py", line 91, in acceptBluetoothConnection
    self.clientSocket, clientInfo = self.serverSocket.accept()
  File "/usr/lib/python2.7/dist-packages/bluetooth/bluez.py", line 129, in accept
    client, addr = self._sock.accept ()
KeyboardInterrupt
[2019-11-13 14:47:21,926] : [ERROR] : [bleClientLogger] : [newSender.py] : [readJsonFile] : Failed to load content from the text.json
Traceback (most recent call last):
  File "newSender.py", line 100, in readJsonFile
    self.jsonObj = json.load(jsonFileObj)
  File "/usr/lib/python2.7/json/__init__.py", line 291, in load
    **kw)
  File "/usr/lib/python2.7/json/__init__.py", line 339, in loads
    return _default_decoder.decode(s)
  File "/usr/lib/python2.7/json/decoder.py", line 364, in decode
    obj, end = self.raw_decode(s, idx=_w(s, 0).end())
  File "/usr/lib/python2.7/json/decoder.py", line 382, in raw_decode
    raise ValueError("No JSON object could be decoded")
ValueError: No JSON object could be decoded
[2019-11-13 14:47:21,930] : [ERROR] : [bleClientLogger] : [newSender.py] : [sendData] : Failed to send data over bluetooth connection
Traceback (most recent call last):
  File "newSender.py", line 119, in sendData
    self.clientSocket.send(_serializedData)
AttributeError: 'NoneType' object has no attribute 'send'
[2019-11-13 14:47:21,931] : [ERROR] : [bleClientLogger] : [newSender.py] : [closeBluetoothSocket] : Failed to close the bluetooth client socket 
Traceback (most recent call last):
  File "newSender.py", line 142, in closeBluetoothSocket
    self.clientSocket.close()
AttributeError: 'NoneType' object has no attribute 'close'
[2019-11-13 14:47:41,800] : [ERROR] : [bleClientLogger] : [newSender.py] : [readJsonFile] : Failed to load content from the text.json
Traceback (most recent call last):
  File "newSender.py", line 100, in readJsonFile
    self.jsonObj = json.load(jsonFileObj)
  File "/usr/lib/python2.7/json/__init__.py", line 291, in load
    **kw)
  File "/usr/lib/python2.7/json/__init__.py", line 339, in loads
    return _default_decoder.decode(s)
  File "/usr/lib/python2.7/json/decoder.py", line 364, in decode
    obj, end = self.raw_decode(s, idx=_w(s, 0).end())
  File "/usr/lib/python2.7/json/decoder.py", line 382, in raw_decode
    raise ValueError("No JSON object could be decoded")
ValueError: No JSON object could be decoded
[2019-11-13 14:47:42,306] : [ERROR] : [bleClientLogger] : [newSender.py] : [sendData] : Failed to send data over bluetooth connection
Traceback (most recent call last):
  File "newSender.py", line 124, in sendData
    dataRecv= self.clientSocket.recv(1024)
  File "<string>", line 5, in recv
BluetoothError: (104, 'Connection reset by peer')
[2019-11-13 14:51:30,672] : [ERROR] : [bleClientLogger] : [newSender.py] : [acceptBluetoothConnection] : Failed to accept bluetooth connection ... 
Traceback (most recent call last):
  File "newSender.py", line 91, in acceptBluetoothConnection
    self.clientSocket, clientInfo = self.serverSocket.accept()
  File "/usr/lib/python2.7/dist-packages/bluetooth/bluez.py", line 129, in accept
    client, addr = self._sock.accept ()
KeyboardInterrupt
[2019-11-13 14:51:30,678] : [ERROR] : [bleClientLogger] : [newSender.py] : [sendData] : Failed to send data over bluetooth connection
Traceback (most recent call last):
  File "newSender.py", line 119, in sendData
    self.clientSocket.send(_serializedData)
AttributeError: 'NoneType' object has no attribute 'send'
[2019-11-13 14:51:30,679] : [ERROR] : [bleClientLogger] : [newSender.py] : [closeBluetoothSocket] : Failed to close the bluetooth client socket 
Traceback (most recent call last):
  File "newSender.py", line 142, in closeBluetoothSocket
    self.clientSocket.close()
AttributeError: 'NoneType' object has no attribute 'close'
[2019-11-13 14:51:48,414] : [ERROR] : [bleClientLogger] : [newSender.py] : [sendData] : Failed to send data over bluetooth connection
Traceback (most recent call last):
  File "newSender.py", line 124, in sendData
    dataRecv= self.clientSocket.recv(1024)
  File "<string>", line 5, in recv
BluetoothError: (104, 'Connection reset by peer')
[2019-11-13 14:52:11,937] : [ERROR] : [bleClientLogger] : [newSender.py] : [sendData] : Failed to send data over bluetooth connection
Traceback (most recent call last):
  File "newSender.py", line 124, in sendData
    dataRecv= self.clientSocket.recv(1024)
  File "<string>", line 5, in recv
BluetoothError: (104, 'Connection reset by peer')
[2019-11-13 14:54:18,710] : [ERROR] : [bleClientLogger] : [newSender.py] : [sendData] : Failed to send data over bluetooth connection
Traceback (most recent call last):
  File "newSender.py", line 123, in sendData
    dataRecv= self.clientSocket.recv(1024)
  File "<string>", line 5, in recv
BluetoothError: (104, 'Connection reset by peer')
[2019-11-13 15:06:45,437] : [ERROR] : [bleClientLogger] : [newSender.py] : [acceptBluetoothConnection] : Failed to accept bluetooth connection ... 
Traceback (most recent call last):
  File "newSender.py", line 91, in acceptBluetoothConnection
    self.clientSocket, clientInfo = self.serverSocket.accept()
  File "/usr/lib/python2.7/dist-packages/bluetooth/bluez.py", line 129, in accept
    client, addr = self._sock.accept ()
KeyboardInterrupt
[2019-11-13 15:06:45,448] : [ERROR] : [bleClientLogger] : [newSender.py] : [sendData] : Failed to send data over bluetooth connection
Traceback (most recent call last):
  File "newSender.py", line 118, in sendData
    self.clientSocket.send(_serializedData)
AttributeError: 'NoneType' object has no attribute 'send'
[2019-11-13 15:06:45,450] : [ERROR] : [bleClientLogger] : [newSender.py] : [closeBluetoothSocket] : Failed to close the bluetooth client socket 
Traceback (most recent call last):
  File "newSender.py", line 141, in closeBluetoothSocket
    self.clientSocket.close()
AttributeError: 'NoneType' object has no attribute 'close'
[2019-11-13 15:08:50,950] : [ERROR] : [bleClientLogger] : [newSender.py] : [sendData] : Failed to send data over bluetooth connection
Traceback (most recent call last):
  File "newSender.py", line 123, in sendData
    dataRecv= self.clientSocket.recv(1024)
  File "<string>", line 5, in recv
BluetoothError: (104, 'Connection reset by peer')
[2019-11-13 15:12:30,484] : [ERROR] : [bleClientLogger] : [newSender.py] : [sendData] : Failed to send data over bluetooth connection
Traceback (most recent call last):
  File "newSender.py", line 123, in sendData
    dataRecv= self.clientSocket.recv(1024)
  File "<string>", line 5, in recv
BluetoothError: (104, 'Connection reset by peer')
[2019-11-13 15:15:20,394] : [ERROR] : [bleClientLogger] : [newSender.py] : [acceptBluetoothConnection] : Failed to accept bluetooth connection ... 
Traceback (most recent call last):
  File "newSender.py", line 91, in acceptBluetoothConnection
    self.clientSocket, clientInfo = self.serverSocket.accept()
  File "/usr/lib/python2.7/dist-packages/bluetooth/bluez.py", line 129, in accept
    client, addr = self._sock.accept ()
KeyboardInterrupt
[2019-11-13 15:15:20,402] : [ERROR] : [bleClientLogger] : [newSender.py] : [sendData] : Failed to send data over bluetooth connection
Traceback (most recent call last):
  File "newSender.py", line 118, in sendData
    self.clientSocket.send(_serializedData)
AttributeError: 'NoneType' object has no attribute 'send'
[2019-11-13 15:15:20,403] : [ERROR] : [bleClientLogger] : [newSender.py] : [closeBluetoothSocket] : Failed to close the bluetooth client socket 
Traceback (most recent call last):
  File "newSender.py", line 141, in closeBluetoothSocket
    self.clientSocket.close()
AttributeError: 'NoneType' object has no attribute 'close'
[2019-11-19 11:17:08,640] : [ERROR] : [bleClientLogger] : [newSender.py] : [acceptBluetoothConnection] : Failed to accept bluetooth connection ... 
Traceback (most recent call last):
  File "newSender.py", line 91, in acceptBluetoothConnection
    self.clientSocket, clientInfo = self.serverSocket.accept()
  File "/usr/lib/python2.7/dist-packages/bluetooth/bluez.py", line 129, in accept
    client, addr = self._sock.accept ()
KeyboardInterrupt
[2019-11-19 11:17:08,648] : [ERROR] : [bleClientLogger] : [newSender.py] : [sendData] : Failed to send data over bluetooth connection
Traceback (most recent call last):
  File "newSender.py", line 118, in sendData
    self.clientSocket.send(_serializedData)
AttributeError: 'NoneType' object has no attribute 'send'
[2019-11-19 11:17:08,649] : [ERROR] : [bleClientLogger] : [newSender.py] : [closeBluetoothSocket] : Failed to close the bluetooth client socket 
Traceback (most recent call last):
  File "newSender.py", line 141, in closeBluetoothSocket
    self.clientSocket.close()
AttributeError: 'NoneType' object has no attribute 'close'
[2019-11-19 11:24:39,901] : [ERROR] : [bleClientLogger] : [newSender.py] : [acceptBluetoothConnection] : Failed to accept bluetooth connection ... 
Traceback (most recent call last):
  File "newSender.py", line 91, in acceptBluetoothConnection
    self.clientSocket, clientInfo = self.serverSocket.accept()
  File "/usr/lib/python2.7/dist-packages/bluetooth/bluez.py", line 129, in accept
    client, addr = self._sock.accept ()
KeyboardInterrupt
[2019-11-19 11:24:39,908] : [ERROR] : [bleClientLogger] : [newSender.py] : [sendData] : Failed to send data over bluetooth connection
Traceback (most recent call last):
  File "newSender.py", line 118, in sendData
    self.clientSocket.send(_serializedData)
AttributeError: 'NoneType' object has no attribute 'send'
[2019-11-19 11:24:39,909] : [ERROR] : [bleClientLogger] : [newSender.py] : [closeBluetoothSocket] : Failed to close the bluetooth client socket 
Traceback (most recent call last):
  File "newSender.py", line 141, in closeBluetoothSocket
    self.clientSocket.close()
AttributeError: 'NoneType' object has no attribute 'close'
[2019-11-19 11:26:47,517] : [ERROR] : [bleClientLogger] : [newSender.py] : [acceptBluetoothConnection] : Failed to accept bluetooth connection ... 
Traceback (most recent call last):
  File "newSender.py", line 91, in acceptBluetoothConnection
    self.clientSocket, clientInfo = self.serverSocket.accept()
  File "/usr/lib/python2.7/dist-packages/bluetooth/bluez.py", line 129, in accept
    client, addr = self._sock.accept ()
KeyboardInterrupt
[2019-11-19 11:26:47,526] : [ERROR] : [bleClientLogger] : [newSender.py] : [sendData] : Failed to send data over bluetooth connection
Traceback (most recent call last):
  File "newSender.py", line 118, in sendData
    self.clientSocket.send(_serializedData)
AttributeError: 'NoneType' object has no attribute 'send'
[2019-11-19 11:26:47,528] : [ERROR] : [bleClientLogger] : [newSender.py] : [closeBluetoothSocket] : Failed to close the bluetooth client socket 
Traceback (most recent call last):
  File "newSender.py", line 141, in closeBluetoothSocket
    self.clientSocket.close()
AttributeError: 'NoneType' object has no attribute 'close'
[2019-11-19 11:27:05,823] : [ERROR] : [bleClientLogger] : [newSender.py] : [sendData] : Failed to send data over bluetooth connection
Traceback (most recent call last):
  File "newSender.py", line 123, in sendData
    dataRecv= self.clientSocket.recv(1024)
  File "<string>", line 5, in recv
BluetoothError: (104, 'Connection reset by peer')
[2019-11-19 11:29:51,943] : [ERROR] : [bleClientLogger] : [newSender.py] : [sendData] : Failed to send data over bluetooth connection
Traceback (most recent call last):
  File "newSender.py", line 123, in sendData
    dataRecv= self.clientSocket.recv(1024)
  File "<string>", line 5, in recv
BluetoothError: (104, 'Connection reset by peer')
[2019-11-19 12:22:37,616] : [ERROR] : [bleClientLogger] : [newSender.py] : [acceptBluetoothConnection] : Failed to accept bluetooth connection ... 
Traceback (most recent call last):
  File "newSender.py", line 91, in acceptBluetoothConnection
    self.clientSocket, clientInfo = self.serverSocket.accept()
  File "/usr/lib/python2.7/dist-packages/bluetooth/bluez.py", line 129, in accept
    client, addr = self._sock.accept ()
KeyboardInterrupt
[2019-11-19 12:22:37,621] : [ERROR] : [bleClientLogger] : [newSender.py] : [readJsonFile] : Failed to load content from the data.json
Traceback (most recent call last):
  File "newSender.py", line 98, in readJsonFile
    jsonFileObj = open(self.jsonFile,"r")
IOError: [Errno 2] No such file or directory: 'data.json'
[2019-11-19 12:22:37,625] : [ERROR] : [bleClientLogger] : [newSender.py] : [sendData] : Failed to send data over bluetooth connection
Traceback (most recent call last):
  File "newSender.py", line 119, in sendData
    self.clientSocket.send(_serializedData)
AttributeError: 'NoneType' object has no attribute 'send'
[2019-11-19 12:22:37,627] : [ERROR] : [bleClientLogger] : [newSender.py] : [closeBluetoothSocket] : Failed to close the bluetooth client socket 
Traceback (most recent call last):
  File "newSender.py", line 142, in closeBluetoothSocket
    self.clientSocket.close()
AttributeError: 'NoneType' object has no attribute 'close'
[2019-11-19 12:23:51,793] : [ERROR] : [bleClientLogger] : [newSender.py] : [acceptBluetoothConnection] : Failed to accept bluetooth connection ... 
Traceback (most recent call last):
  File "newSender.py", line 91, in acceptBluetoothConnection
    self.clientSocket, clientInfo = self.serverSocket.accept()
  File "/usr/lib/python2.7/dist-packages/bluetooth/bluez.py", line 129, in accept
    client, addr = self._sock.accept ()
KeyboardInterrupt
[2019-11-19 12:23:51,798] : [ERROR] : [bleClientLogger] : [newSender.py] : [readJsonFile] : Failed to load content from the data.json
Traceback (most recent call last):
  File "newSender.py", line 98, in readJsonFile
    jsonFileObj = open(self.jsonFile,"r")
IOError: [Errno 2] No such file or directory: 'data.json'
[2019-11-19 12:23:51,801] : [ERROR] : [bleClientLogger] : [newSender.py] : [sendData] : Failed to send data over bluetooth connection
Traceback (most recent call last):
  File "newSender.py", line 119, in sendData
    self.clientSocket.send(_serializedData)
AttributeError: 'NoneType' object has no attribute 'send'
[2019-11-19 12:23:51,803] : [ERROR] : [bleClientLogger] : [newSender.py] : [closeBluetoothSocket] : Failed to close the bluetooth client socket 
Traceback (most recent call last):
  File "newSender.py", line 142, in closeBluetoothSocket
    self.clientSocket.close()
AttributeError: 'NoneType' object has no attribute 'close'
[2019-11-19 12:24:01,663] : [ERROR] : [bleClientLogger] : [newSender.py] : [readJsonFile] : Failed to load content from the data.json
Traceback (most recent call last):
  File "newSender.py", line 98, in readJsonFile
    jsonFileObj = open(self.jsonFile,"r")
IOError: [Errno 2] No such file or directory: 'data.json'
[2019-11-19 12:24:53,071] : [ERROR] : [bleClientLogger] : [newSender.py] : [sendData] : Failed to send data over bluetooth connection
Traceback (most recent call last):
  File "newSender.py", line 124, in sendData
    dataRecv= self.clientSocket.recv(1024)
  File "<string>", line 5, in recv
BluetoothError: (104, 'Connection reset by peer')
[2019-11-19 12:27:10,245] : [ERROR] : [bleClientLogger] : [newSender.py] : [sendData] : Failed to send data over bluetooth connection
Traceback (most recent call last):
  File "newSender.py", line 124, in sendData
    dataRecv= self.clientSocket.recv(1024)
  File "<string>", line 5, in recv
BluetoothError: (104, 'Connection reset by peer')
[2019-11-19 12:28:31,051] : [ERROR] : [bleClientLogger] : [newSender.py] : [sendData] : Failed to send data over bluetooth connection
Traceback (most recent call last):
  File "newSender.py", line 124, in sendData
    dataRecv= self.clientSocket.recv(1024)
  File "<string>", line 5, in recv
BluetoothError: (104, 'Connection reset by peer')
[2019-11-19 12:33:59,251] : [ERROR] : [bleClientLogger] : [newSender.py] : [sendData] : Failed to send data over bluetooth connection
Traceback (most recent call last):
  File "newSender.py", line 124, in sendData
    dataRecv= self.clientSocket.recv(1024)
  File "<string>", line 5, in recv
BluetoothError: (104, 'Connection reset by peer')
[2019-11-19 12:33:59,255] : [ERROR] : [bleClientLogger] : [newSender.py] : [sendData] : Failed to send data over bluetooth connection
Traceback (most recent call last):
  File "newSender.py", line 119, in sendData
    self.clientSocket.send(_serializedData)
  File "<string>", line 5, in send
BluetoothError: (107, 'Transport endpoint is not connected')
[2019-11-19 12:38:46,694] : [ERROR] : [bleClientLogger] : [newSender.py] : [acceptBluetoothConnection] : Failed to accept bluetooth connection ... 
Traceback (most recent call last):
  File "newSender.py", line 92, in acceptBluetoothConnection
    self.clientSocket, clientInfo = self.serverSocket.accept()
  File "/usr/lib/python2.7/dist-packages/bluetooth/bluez.py", line 129, in accept
    client, addr = self._sock.accept ()
KeyboardInterrupt
[2019-11-19 12:38:46,703] : [ERROR] : [bleClientLogger] : [newSender.py] : [sendData] : Failed to send data over bluetooth connection
Traceback (most recent call last):
  File "newSender.py", line 120, in sendData
    # _serializedData = str(len(_serializedData))+ ":"+_serializedData
AttributeError: 'NoneType' object has no attribute 'send'
[2019-11-19 12:38:46,706] : [ERROR] : [bleClientLogger] : [newSender.py] : [sendData] : Failed to send data over bluetooth connection
Traceback (most recent call last):
  File "newSender.py", line 120, in sendData
    # _serializedData = str(len(_serializedData))+ ":"+_serializedData
AttributeError: 'NoneType' object has no attribute 'send'
[2019-11-19 12:38:46,708] : [ERROR] : [bleClientLogger] : [newSender.py] : [closeBluetoothSocket] : Failed to close the bluetooth client socket 
Traceback (most recent call last):
  File "newSender.py", line 143, in closeBluetoothSocket
    def closeBluetoothSocket(self):
AttributeError: 'NoneType' object has no attribute 'close'
[2019-11-19 12:40:12,402] : [ERROR] : [bleClientLogger] : [newSender.py] : [sendData] : Failed to send data over bluetooth connection
Traceback (most recent call last):
  File "newSender.py", line 127, in sendData
    dataRecv= self.clientSocket.recv(1024)
  File "<string>", line 5, in recv
BluetoothError: (104, 'Connection reset by peer')
[2019-11-19 12:42:41,646] : [ERROR] : [bleClientLogger] : [newSender.py] : [acceptBluetoothConnection] : Failed to accept bluetooth connection ... 
Traceback (most recent call last):
  File "newSender.py", line 92, in acceptBluetoothConnection
    self.clientSocket, clientInfo = self.serverSocket.accept()
  File "/usr/lib/python2.7/dist-packages/bluetooth/bluez.py", line 129, in accept
    client, addr = self._sock.accept ()
KeyboardInterrupt
[2019-11-19 12:42:41,654] : [ERROR] : [bleClientLogger] : [newSender.py] : [sendData] : Failed to send data over bluetooth connection
Traceback (most recent call last):
  File "newSender.py", line 122, in sendData
    self.clientSocket.send(_serializedData)
AttributeError: 'NoneType' object has no attribute 'send'
[2019-11-19 12:42:41,656] : [ERROR] : [bleClientLogger] : [newSender.py] : [closeBluetoothSocket] : Failed to close the bluetooth client socket 
Traceback (most recent call last):
  File "newSender.py", line 145, in closeBluetoothSocket
    self.clientSocket.close()
AttributeError: 'NoneType' object has no attribute 'close'
[2019-11-19 12:44:19,617] : [ERROR] : [bleClientLogger] : [newSender.py] : [sendData] : Failed to send data over bluetooth connection
Traceback (most recent call last):
  File "newSender.py", line 127, in sendData
    dataRecv= self.clientSocket.recv(1024)
  File "<string>", line 5, in recv
BluetoothError: (104, 'Connection reset by peer')
[2019-11-19 13:17:07,220] : [ERROR] : [bleClientLogger] : [newSender.py] : [acceptBluetoothConnection] : Failed to accept bluetooth connection ... 
Traceback (most recent call last):
  File "newSender.py", line 92, in acceptBluetoothConnection
    self.clientSocket, clientInfo = self.serverSocket.accept()
  File "/usr/lib/python2.7/dist-packages/bluetooth/bluez.py", line 129, in accept
    client, addr = self._sock.accept ()
KeyboardInterrupt
[2019-11-19 13:17:07,228] : [ERROR] : [bleClientLogger] : [newSender.py] : [sendData] : Failed to send data over bluetooth connection
Traceback (most recent call last):
  File "newSender.py", line 122, in sendData
    self.clientSocket.send(_serializedData)
AttributeError: 'NoneType' object has no attribute 'send'
[2019-11-19 13:17:07,229] : [ERROR] : [bleClientLogger] : [newSender.py] : [closeBluetoothSocket] : Failed to close the bluetooth client socket 
Traceback (most recent call last):
  File "newSender.py", line 145, in closeBluetoothSocket
    self.clientSocket.close()
AttributeError: 'NoneType' object has no attribute 'close'
[2019-11-19 13:27:43,461] : [ERROR] : [bleClientLogger] : [newSender.py] : [acceptBluetoothConnection] : Failed to accept bluetooth connection ... 
Traceback (most recent call last):
  File "newSender.py", line 92, in acceptBluetoothConnection
    self.clientSocket, clientInfo = self.serverSocket.accept()
  File "/usr/lib/python2.7/dist-packages/bluetooth/bluez.py", line 129, in accept
    client, addr = self._sock.accept ()
KeyboardInterrupt
[2019-11-19 13:27:43,471] : [ERROR] : [bleClientLogger] : [newSender.py] : [sendData] : Failed to send data over bluetooth connection
Traceback (most recent call last):
  File "newSender.py", line 122, in sendData
    self.clientSocket.send(_serializedData)
AttributeError: 'NoneType' object has no attribute 'send'
[2019-11-19 13:27:43,473] : [ERROR] : [bleClientLogger] : [newSender.py] : [closeBluetoothSocket] : Failed to close the bluetooth client socket 
Traceback (most recent call last):
  File "newSender.py", line 145, in closeBluetoothSocket
    self.clientSocket.close()
AttributeError: 'NoneType' object has no attribute 'close'
[2019-11-19 13:32:03,881] : [ERROR] : [bleClientLogger] : [newSender.py] : [acceptBluetoothConnection] : Failed to accept bluetooth connection ... 
Traceback (most recent call last):
  File "newSender.py", line 92, in acceptBluetoothConnection
    self.clientSocket, clientInfo = self.serverSocket.accept()
  File "/usr/lib/python2.7/dist-packages/bluetooth/bluez.py", line 129, in accept
    client, addr = self._sock.accept ()
KeyboardInterrupt
[2019-11-19 13:32:03,890] : [ERROR] : [bleClientLogger] : [newSender.py] : [sendData] : Failed to send data over bluetooth connection
Traceback (most recent call last):
  File "newSender.py", line 122, in sendData
    self.clientSocket.send(_serializedData)
AttributeError: 'NoneType' object has no attribute 'send'
[2019-11-19 13:32:03,891] : [ERROR] : [bleClientLogger] : [newSender.py] : [closeBluetoothSocket] : Failed to close the bluetooth client socket 
Traceback (most recent call last):
  File "newSender.py", line 145, in closeBluetoothSocket
    self.clientSocket.close()
AttributeError: 'NoneType' object has no attribute 'close'
[2019-11-19 13:39:35,589] : [ERROR] : [bleClientLogger] : [newSender.py] : [acceptBluetoothConnection] : Failed to accept bluetooth connection ... 
Traceback (most recent call last):
  File "newSender.py", line 92, in acceptBluetoothConnection
    self.clientSocket, clientInfo = self.serverSocket.accept()
  File "/usr/lib/python2.7/dist-packages/bluetooth/bluez.py", line 129, in accept
    client, addr = self._sock.accept ()
KeyboardInterrupt
[2019-11-19 13:39:35,598] : [ERROR] : [bleClientLogger] : [newSender.py] : [sendData] : Failed to send data over bluetooth connection
Traceback (most recent call last):
  File "newSender.py", line 122, in sendData
    self.clientSocket.send(_serializedData)
AttributeError: 'NoneType' object has no attribute 'send'
[2019-11-19 13:39:35,599] : [ERROR] : [bleClientLogger] : [newSender.py] : [closeBluetoothSocket] : Failed to close the bluetooth client socket 
Traceback (most recent call last):
  File "newSender.py", line 145, in closeBluetoothSocket
    self.clientSocket.close()
AttributeError: 'NoneType' object has no attribute 'close'
[2019-11-19 13:40:54,047] : [ERROR] : [bleClientLogger] : [newSender.py] : [sendData] : Failed to send data over bluetooth connection
Traceback (most recent call last):
  File "newSender.py", line 127, in sendData
    dataRecv= self.clientSocket.recv(1024)
  File "<string>", line 5, in recv
BluetoothError: (104, 'Connection reset by peer')
[2019-11-19 13:42:51,344] : [ERROR] : [bleClientLogger] : [newSender.py] : [sendData] : Failed to send data over bluetooth connection
Traceback (most recent call last):
  File "newSender.py", line 127, in sendData
    dataRecv= self.clientSocket.recv(1024)
  File "<string>", line 5, in recv
BluetoothError: (104, 'Connection reset by peer')
[2019-11-19 13:44:38,898] : [ERROR] : [bleClientLogger] : [newSender.py] : [sendData] : Failed to send data over bluetooth connection
Traceback (most recent call last):
  File "newSender.py", line 127, in sendData
    dataRecv= self.clientSocket.recv(1024)
  File "<string>", line 5, in recv
BluetoothError: (104, 'Connection reset by peer')
[2019-11-19 13:46:46,647] : [ERROR] : [bleClientLogger] : [newSender.py] : [acceptBluetoothConnection] : Failed to accept bluetooth connection ... 
Traceback (most recent call last):
  File "newSender.py", line 92, in acceptBluetoothConnection
    self.clientSocket, clientInfo = self.serverSocket.accept()
  File "/usr/lib/python2.7/dist-packages/bluetooth/bluez.py", line 129, in accept
    client, addr = self._sock.accept ()
KeyboardInterrupt
[2019-11-19 13:46:46,657] : [ERROR] : [bleClientLogger] : [newSender.py] : [sendData] : Failed to send data over bluetooth connection
Traceback (most recent call last):
  File "newSender.py", line 122, in sendData
    self.clientSocket.send(_serializedData)
AttributeError: 'NoneType' object has no attribute 'send'
[2019-11-19 13:46:46,659] : [ERROR] : [bleClientLogger] : [newSender.py] : [closeBluetoothSocket] : Failed to close the bluetooth client socket 
Traceback (most recent call last):
  File "newSender.py", line 145, in closeBluetoothSocket
    self.clientSocket.close()
AttributeError: 'NoneType' object has no attribute 'close'
[2019-11-19 13:48:01,215] : [ERROR] : [bleClientLogger] : [newSender.py] : [sendData] : Failed to send data over bluetooth connection
Traceback (most recent call last):
  File "newSender.py", line 127, in sendData
    dataRecv= self.clientSocket.recv(1024)
  File "<string>", line 5, in recv
BluetoothError: (104, 'Connection reset by peer')
[2019-11-19 13:49:24,073] : [ERROR] : [bleClientLogger] : [newSender.py] : [sendData] : Failed to send data over bluetooth connection
Traceback (most recent call last):
  File "newSender.py", line 127, in sendData
    dataRecv= self.clientSocket.recv(1024)
  File "<string>", line 5, in recv
BluetoothError: (104, 'Connection reset by peer')
